Internal Server Error: /
Traceback (most recent call last):
  File "C:\Users\asati\AppData\Roaming\Python\Python313\site-packages\django\core\handlers\exception.py", line 55, in inner
    response = get_response(request)
  File "C:\Users\asati\AppData\Roaming\Python\Python313\site-packages\django\core\handlers\base.py", line 197, in _get_response
    response = wrapped_callback(request, *callback_args, **callback_kwargs)
  File "C:\Users\asati\OneDrive\Desktop\Live Projects\Type2Test\Type2Speed\typing_app\views.py", line 45, in home_view
    column_size = 12 // min(exam_count, 4)  # Dynamically calculate the column size
                  ~~~^^~~~~~~~~~~~~~~~~~~~
ZeroDivisionError: integer division or modulo by zero
"GET / HTTP/1.1" 500 74260
Internal Server Error: /
Traceback (most recent call last):
  File "C:\Users\asati\AppData\Roaming\Python\Python313\site-packages\django\core\handlers\exception.py", line 55, in inner
    response = get_response(request)
  File "C:\Users\asati\AppData\Roaming\Python\Python313\site-packages\django\core\handlers\base.py", line 197, in _get_response
    response = wrapped_callback(request, *callback_args, **callback_kwargs)
  File "C:\Users\asati\OneDrive\Desktop\Live Projects\Type2Test\Type2Speed\typing_app\views.py", line 45, in home_view
    column_size = 12 // min(exam_count, 4)  # Dynamically calculate the column size
                  ~~~^^~~~~~~~~~~~~~~~~~~~
ZeroDivisionError: integer division or modulo by zero
"GET / HTTP/1.1" 500 74111
Internal Server Error: /test-result/CPCT/
Traceback (most recent call last):
  File "C:\Users\asati\AppData\Roaming\Python\Python313\site-packages\django\core\handlers\exception.py", line 55, in inner
    response = get_response(request)
  File "C:\Users\asati\AppData\Roaming\Python\Python313\site-packages\django\core\handlers\base.py", line 197, in _get_response
    response = wrapped_callback(request, *callback_args, **callback_kwargs)
  File "C:\Users\asati\OneDrive\Desktop\Live Projects\Type2Test\Type2Speed\typing_app\views.py", line 402, in test_result_view
    passage = re.sub(r'\s+', ' ', exam_content.passage.strip())
                                  ^^^^^^^^^^^^^^^^^^^^
AttributeError: 'ExamContent' object has no attribute 'passage'
"POST /test-result/CPCT/ HTTP/1.1" 500 78494
"GET /typing-test/PRACTISE/english/127/ HTTP/1.1" 500 77277
"GET /typing-test/PRACTISE/english/127/ HTTP/1.1" 500 77277
"GET /typing-test/PRACTISE/english/127/ HTTP/1.1" 500 77277
Internal Server Error: /test-result/CPCT/
Traceback (most recent call last):
  File "C:\Users\asati\AppData\Roaming\Python\Python313\site-packages\django\core\handlers\exception.py", line 55, in inner
    response = get_response(request)
  File "C:\Users\asati\AppData\Roaming\Python\Python313\site-packages\django\core\handlers\base.py", line 197, in _get_response
    response = wrapped_callback(request, *callback_args, **callback_kwargs)
  File "C:\Users\asati\OneDrive\Desktop\Live Projects\Type2Test\Type2Speed\typing_app\views.py", line 408, in test_result_view
    passage = re.sub(r'\s+', ' ', exam_content.passage_english.strip())  # Use passage_english
                                  ^^^^^^^^^^^^^^^^^^^^^^^^^^^^^^^^^^
AttributeError: 'NoneType' object has no attribute 'strip'
"POST /test-result/CPCT/ HTTP/1.1" 500 78534
Internal Server Error: /ads.txt/
Traceback (most recent call last):
  File "C:\Users\asati\AppData\Roaming\Python\Python313\site-packages\django\core\handlers\exception.py", line 55, in inner
    response = get_response(request)
  File "C:\Users\asati\AppData\Roaming\Python\Python313\site-packages\django\core\handlers\base.py", line 197, in _get_response
    response = wrapped_callback(request, *callback_args, **callback_kwargs)
TypeError: ads_get() missing 1 required positional argument: 'request'
"GET /ads.txt/ HTTP/1.1" 500 69922
Internal Server Error: /sitemap.xml
Traceback (most recent call last):
  File "C:\Users\asati\AppData\Roaming\Python\Python313\site-packages\django\core\handlers\exception.py", line 55, in inner
    response = get_response(request)
  File "C:\Users\asati\AppData\Roaming\Python\Python313\site-packages\django\core\handlers\base.py", line 197, in _get_response
    response = wrapped_callback(request, *callback_args, **callback_kwargs)
  File "C:\Users\asati\AppData\Roaming\Python\Python313\site-packages\django\contrib\sitemaps\views.py", line 23, in inner
    response = func(request, *args, **kwargs)
  File "C:\Users\asati\AppData\Roaming\Python\Python313\site-packages\django\contrib\sitemaps\views.py", line 117, in sitemap
    urls.extend(site.get_urls(page=page, site=req_site, protocol=req_protocol))
                ~~~~~~~~~~~~~^^^^^^^^^^^^^^^^^^^^^^^^^^^^^^^^^^^^^^^^^^^^^^^^^
  File "C:\Users\asati\AppData\Roaming\Python\Python313\site-packages\django\contrib\sitemaps\__init__.py", line 104, in get_urls
    return self._urls(page, protocol, domain)
           ~~~~~~~~~~^^^^^^^^^^^^^^^^^^^^^^^^
  File "C:\Users\asati\AppData\Roaming\Python\Python313\site-packages\django\contrib\sitemaps\__init__.py", line 124, in _urls
    loc = f"{protocol}://{domain}{self._location(item)}"
                                  ~~~~~~~~~~~~~~^^^^^^
  File "C:\Users\asati\AppData\Roaming\Python\Python313\site-packages\django\contrib\sitemaps\__init__.py", line 69, in _location
    return self._get("location", item)
           ~~~~~~~~~^^^^^^^^^^^^^^^^^^
  File "C:\Users\asati\AppData\Roaming\Python\Python313\site-packages\django\contrib\sitemaps\__init__.py", line 39, in _get
    return attr(item)
  File "C:\Users\asati\OneDrive\Desktop\Live Projects\Type2Test\Type2Speed\typing_app\sitemaps.py", line 7, in location
    return reverse(item)
  File "C:\Users\asati\AppData\Roaming\Python\Python313\site-packages\django\urls\base.py", line 88, in reverse
    return resolver._reverse_with_prefix(view, prefix, *args, **kwargs)
           ~~~~~~~~~~~~~~~~~~~~~~~~~~~~~^^^^^^^^^^^^^^^^^^^^^^^^^^^^^^^
  File "C:\Users\asati\AppData\Roaming\Python\Python313\site-packages\django\urls\resolvers.py", line 831, in _reverse_with_prefix
    raise NoReverseMatch(msg)
django.urls.exceptions.NoReverseMatch: Reverse for 'about' not found. 'about' is not a valid view function or pattern name.
"GET /sitemap.xml HTTP/1.1" 500 110757
Internal Server Error: /sitemap.xml
Traceback (most recent call last):
  File "C:\Users\asati\AppData\Roaming\Python\Python313\site-packages\django\core\handlers\exception.py", line 55, in inner
    response = get_response(request)
  File "C:\Users\asati\AppData\Roaming\Python\Python313\site-packages\django\core\handlers\base.py", line 197, in _get_response
    response = wrapped_callback(request, *callback_args, **callback_kwargs)
  File "C:\Users\asati\AppData\Roaming\Python\Python313\site-packages\django\contrib\sitemaps\views.py", line 23, in inner
    response = func(request, *args, **kwargs)
  File "C:\Users\asati\AppData\Roaming\Python\Python313\site-packages\django\contrib\sitemaps\views.py", line 117, in sitemap
    urls.extend(site.get_urls(page=page, site=req_site, protocol=req_protocol))
                ~~~~~~~~~~~~~^^^^^^^^^^^^^^^^^^^^^^^^^^^^^^^^^^^^^^^^^^^^^^^^^
  File "C:\Users\asati\AppData\Roaming\Python\Python313\site-packages\django\contrib\sitemaps\__init__.py", line 104, in get_urls
    return self._urls(page, protocol, domain)
           ~~~~~~~~~~^^^^^^^^^^^^^^^^^^^^^^^^
  File "C:\Users\asati\AppData\Roaming\Python\Python313\site-packages\django\contrib\sitemaps\__init__.py", line 124, in _urls
    loc = f"{protocol}://{domain}{self._location(item)}"
                                  ~~~~~~~~~~~~~~^^^^^^
  File "C:\Users\asati\AppData\Roaming\Python\Python313\site-packages\django\contrib\sitemaps\__init__.py", line 69, in _location
    return self._get("location", item)
           ~~~~~~~~~^^^^^^^^^^^^^^^^^^
  File "C:\Users\asati\AppData\Roaming\Python\Python313\site-packages\django\contrib\sitemaps\__init__.py", line 39, in _get
    return attr(item)
  File "C:\Users\asati\OneDrive\Desktop\Live Projects\Type2Test\Type2Speed\typing_app\sitemaps.py", line 10, in location
    return reverse(item)
  File "C:\Users\asati\AppData\Roaming\Python\Python313\site-packages\django\urls\base.py", line 88, in reverse
    return resolver._reverse_with_prefix(view, prefix, *args, **kwargs)
           ~~~~~~~~~~~~~~~~~~~~~~~~~~~~~^^^^^^^^^^^^^^^^^^^^^^^^^^^^^^^
  File "C:\Users\asati\AppData\Roaming\Python\Python313\site-packages\django\urls\resolvers.py", line 831, in _reverse_with_prefix
    raise NoReverseMatch(msg)
django.urls.exceptions.NoReverseMatch: Reverse for 'instructions' with no arguments not found. 1 pattern(s) tried: ['instructions/(?P<exam_type>[^/]+)/(?P<passage_id>[0-9]+)/\\Z']
"GET /sitemap.xml HTTP/1.1" 500 115432
Internal Server Error: /sitemap.xml
Traceback (most recent call last):
  File "C:\Users\asati\AppData\Roaming\Python\Python313\site-packages\django\core\handlers\exception.py", line 55, in inner
    response = get_response(request)
  File "C:\Users\asati\AppData\Roaming\Python\Python313\site-packages\django\core\handlers\base.py", line 197, in _get_response
    response = wrapped_callback(request, *callback_args, **callback_kwargs)
  File "C:\Users\asati\AppData\Roaming\Python\Python313\site-packages\django\contrib\sitemaps\views.py", line 23, in inner
    response = func(request, *args, **kwargs)
  File "C:\Users\asati\AppData\Roaming\Python\Python313\site-packages\django\contrib\sitemaps\views.py", line 117, in sitemap
    urls.extend(site.get_urls(page=page, site=req_site, protocol=req_protocol))
                ~~~~~~~~~~~~~^^^^^^^^^^^^^^^^^^^^^^^^^^^^^^^^^^^^^^^^^^^^^^^^^
  File "C:\Users\asati\AppData\Roaming\Python\Python313\site-packages\django\contrib\sitemaps\__init__.py", line 104, in get_urls
    return self._urls(page, protocol, domain)
           ~~~~~~~~~~^^^^^^^^^^^^^^^^^^^^^^^^
  File "C:\Users\asati\AppData\Roaming\Python\Python313\site-packages\django\contrib\sitemaps\__init__.py", line 124, in _urls
    loc = f"{protocol}://{domain}{self._location(item)}"
                                  ~~~~~~~~~~~~~~^^^^^^
  File "C:\Users\asati\AppData\Roaming\Python\Python313\site-packages\django\contrib\sitemaps\__init__.py", line 69, in _location
    return self._get("location", item)
           ~~~~~~~~~^^^^^^^^^^^^^^^^^^
  File "C:\Users\asati\AppData\Roaming\Python\Python313\site-packages\django\contrib\sitemaps\__init__.py", line 39, in _get
    return attr(item)
  File "C:\Users\asati\OneDrive\Desktop\Live Projects\Type2Test\Type2Speed\typing_app\sitemaps.py", line 10, in location
    return reverse(item)
  File "C:\Users\asati\AppData\Roaming\Python\Python313\site-packages\django\urls\base.py", line 88, in reverse
    return resolver._reverse_with_prefix(view, prefix, *args, **kwargs)
           ~~~~~~~~~~~~~~~~~~~~~~~~~~~~~^^^^^^^^^^^^^^^^^^^^^^^^^^^^^^^
  File "C:\Users\asati\AppData\Roaming\Python\Python313\site-packages\django\urls\resolvers.py", line 831, in _reverse_with_prefix
    raise NoReverseMatch(msg)
django.urls.exceptions.NoReverseMatch: Reverse for 'games' not found. 'games' is not a valid view function or pattern name.
"GET /sitemap.xml HTTP/1.1" 500 114575
Internal Server Error: /sitemap.xml
Traceback (most recent call last):
  File "C:\Users\asati\AppData\Roaming\Python\Python313\site-packages\django\core\handlers\exception.py", line 55, in inner
    response = get_response(request)
  File "C:\Users\asati\AppData\Roaming\Python\Python313\site-packages\django\core\handlers\base.py", line 220, in _get_response
    response = response.render()
  File "C:\Users\asati\AppData\Roaming\Python\Python313\site-packages\django\template\response.py", line 114, in render
    self.content = self.rendered_content
                   ^^^^^^^^^^^^^^^^^^^^^
  File "C:\Users\asati\AppData\Roaming\Python\Python313\site-packages\django\template\response.py", line 90, in rendered_content
    template = self.resolve_template(self.template_name)
  File "C:\Users\asati\AppData\Roaming\Python\Python313\site-packages\django\template\response.py", line 74, in resolve_template
    return get_template(template, using=self.using)
  File "C:\Users\asati\AppData\Roaming\Python\Python313\site-packages\django\template\loader.py", line 19, in get_template
    raise TemplateDoesNotExist(template_name, chain=chain)
django.template.exceptions.TemplateDoesNotExist: sitemap.xml
"GET /sitemap.xml HTTP/1.1" 500 87573
Internal Server Error: /sitemap.xml
Traceback (most recent call last):
  File "C:\Users\asati\AppData\Roaming\Python\Python313\site-packages\django\core\handlers\exception.py", line 55, in inner
    response = get_response(request)
  File "C:\Users\asati\AppData\Roaming\Python\Python313\site-packages\django\core\handlers\base.py", line 220, in _get_response
    response = response.render()
  File "C:\Users\asati\AppData\Roaming\Python\Python313\site-packages\django\template\response.py", line 114, in render
    self.content = self.rendered_content
                   ^^^^^^^^^^^^^^^^^^^^^
  File "C:\Users\asati\AppData\Roaming\Python\Python313\site-packages\django\template\response.py", line 90, in rendered_content
    template = self.resolve_template(self.template_name)
  File "C:\Users\asati\AppData\Roaming\Python\Python313\site-packages\django\template\response.py", line 74, in resolve_template
    return get_template(template, using=self.using)
  File "C:\Users\asati\AppData\Roaming\Python\Python313\site-packages\django\template\loader.py", line 19, in get_template
    raise TemplateDoesNotExist(template_name, chain=chain)
django.template.exceptions.TemplateDoesNotExist: sitemap.xml
"GET /sitemap.xml HTTP/1.1" 500 87573
Internal Server Error: /sitemap.xml
Traceback (most recent call last):
  File "C:\Users\asati\AppData\Roaming\Python\Python313\site-packages\django\core\handlers\exception.py", line 55, in inner
    response = get_response(request)
  File "C:\Users\asati\AppData\Roaming\Python\Python313\site-packages\django\core\handlers\base.py", line 220, in _get_response
    response = response.render()
  File "C:\Users\asati\AppData\Roaming\Python\Python313\site-packages\django\template\response.py", line 114, in render
    self.content = self.rendered_content
                   ^^^^^^^^^^^^^^^^^^^^^
  File "C:\Users\asati\AppData\Roaming\Python\Python313\site-packages\django\template\response.py", line 90, in rendered_content
    template = self.resolve_template(self.template_name)
  File "C:\Users\asati\AppData\Roaming\Python\Python313\site-packages\django\template\response.py", line 74, in resolve_template
    return get_template(template, using=self.using)
  File "C:\Users\asati\AppData\Roaming\Python\Python313\site-packages\django\template\loader.py", line 19, in get_template
    raise TemplateDoesNotExist(template_name, chain=chain)
django.template.exceptions.TemplateDoesNotExist: sitemap.xml
"GET /sitemap.xml HTTP/1.1" 500 87764
Internal Server Error: /sitemap.xml
Traceback (most recent call last):
  File "C:\Users\asati\AppData\Roaming\Python\Python313\site-packages\django\core\handlers\exception.py", line 55, in inner
    response = get_response(request)
  File "C:\Users\asati\AppData\Roaming\Python\Python313\site-packages\django\core\handlers\base.py", line 220, in _get_response
    response = response.render()
  File "C:\Users\asati\AppData\Roaming\Python\Python313\site-packages\django\template\response.py", line 114, in render
    self.content = self.rendered_content
                   ^^^^^^^^^^^^^^^^^^^^^
  File "C:\Users\asati\AppData\Roaming\Python\Python313\site-packages\django\template\response.py", line 90, in rendered_content
    template = self.resolve_template(self.template_name)
  File "C:\Users\asati\AppData\Roaming\Python\Python313\site-packages\django\template\response.py", line 74, in resolve_template
    return get_template(template, using=self.using)
  File "C:\Users\asati\AppData\Roaming\Python\Python313\site-packages\django\template\loader.py", line 19, in get_template
    raise TemplateDoesNotExist(template_name, chain=chain)
django.template.exceptions.TemplateDoesNotExist: sitemap.xml
"GET /sitemap.xml HTTP/1.1" 500 87764
Internal Server Error: /sitemap.xml
Traceback (most recent call last):
  File "C:\Users\asati\AppData\Roaming\Python\Python313\site-packages\django\core\handlers\exception.py", line 55, in inner
    response = get_response(request)
  File "C:\Users\asati\AppData\Roaming\Python\Python313\site-packages\django\core\handlers\base.py", line 220, in _get_response
    response = response.render()
  File "C:\Users\asati\AppData\Roaming\Python\Python313\site-packages\django\template\response.py", line 114, in render
    self.content = self.rendered_content
                   ^^^^^^^^^^^^^^^^^^^^^
  File "C:\Users\asati\AppData\Roaming\Python\Python313\site-packages\django\template\response.py", line 90, in rendered_content
    template = self.resolve_template(self.template_name)
  File "C:\Users\asati\AppData\Roaming\Python\Python313\site-packages\django\template\response.py", line 74, in resolve_template
    return get_template(template, using=self.using)
  File "C:\Users\asati\AppData\Roaming\Python\Python313\site-packages\django\template\loader.py", line 19, in get_template
    raise TemplateDoesNotExist(template_name, chain=chain)
django.template.exceptions.TemplateDoesNotExist: sitemap.xml
"GET /sitemap.xml HTTP/1.1" 500 87764
Internal Server Error: /sitemap.xml
Traceback (most recent call last):
  File "C:\Users\asati\AppData\Roaming\Python\Python313\site-packages\django\core\handlers\exception.py", line 55, in inner
    response = get_response(request)
  File "C:\Users\asati\AppData\Roaming\Python\Python313\site-packages\django\core\handlers\base.py", line 220, in _get_response
    response = response.render()
  File "C:\Users\asati\AppData\Roaming\Python\Python313\site-packages\django\template\response.py", line 114, in render
    self.content = self.rendered_content
                   ^^^^^^^^^^^^^^^^^^^^^
  File "C:\Users\asati\AppData\Roaming\Python\Python313\site-packages\django\template\response.py", line 90, in rendered_content
    template = self.resolve_template(self.template_name)
  File "C:\Users\asati\AppData\Roaming\Python\Python313\site-packages\django\template\response.py", line 74, in resolve_template
    return get_template(template, using=self.using)
  File "C:\Users\asati\AppData\Roaming\Python\Python313\site-packages\django\template\loader.py", line 19, in get_template
    raise TemplateDoesNotExist(template_name, chain=chain)
django.template.exceptions.TemplateDoesNotExist: sitemap.xml
"GET /sitemap.xml HTTP/1.1" 500 87764
Internal Server Error: /sitemap.xml
Traceback (most recent call last):
  File "C:\Users\asati\AppData\Roaming\Python\Python313\site-packages\django\core\handlers\exception.py", line 55, in inner
    response = get_response(request)
  File "C:\Users\asati\AppData\Roaming\Python\Python313\site-packages\django\core\handlers\base.py", line 220, in _get_response
    response = response.render()
  File "C:\Users\asati\AppData\Roaming\Python\Python313\site-packages\django\template\response.py", line 114, in render
    self.content = self.rendered_content
                   ^^^^^^^^^^^^^^^^^^^^^
  File "C:\Users\asati\AppData\Roaming\Python\Python313\site-packages\django\template\response.py", line 90, in rendered_content
    template = self.resolve_template(self.template_name)
  File "C:\Users\asati\AppData\Roaming\Python\Python313\site-packages\django\template\response.py", line 74, in resolve_template
    return get_template(template, using=self.using)
  File "C:\Users\asati\AppData\Roaming\Python\Python313\site-packages\django\template\loader.py", line 19, in get_template
    raise TemplateDoesNotExist(template_name, chain=chain)
django.template.exceptions.TemplateDoesNotExist: sitemap.xml
"GET /sitemap.xml HTTP/1.1" 500 87764
Internal Server Error: /sitemap.xml
Traceback (most recent call last):
  File "C:\Users\asati\AppData\Roaming\Python\Python313\site-packages\django\core\handlers\exception.py", line 55, in inner
    response = get_response(request)
  File "C:\Users\asati\AppData\Roaming\Python\Python313\site-packages\django\core\handlers\base.py", line 220, in _get_response
    response = response.render()
  File "C:\Users\asati\AppData\Roaming\Python\Python313\site-packages\django\template\response.py", line 114, in render
    self.content = self.rendered_content
                   ^^^^^^^^^^^^^^^^^^^^^
  File "C:\Users\asati\AppData\Roaming\Python\Python313\site-packages\django\template\response.py", line 90, in rendered_content
    template = self.resolve_template(self.template_name)
  File "C:\Users\asati\AppData\Roaming\Python\Python313\site-packages\django\template\response.py", line 74, in resolve_template
    return get_template(template, using=self.using)
  File "C:\Users\asati\AppData\Roaming\Python\Python313\site-packages\django\template\loader.py", line 19, in get_template
    raise TemplateDoesNotExist(template_name, chain=chain)
django.template.exceptions.TemplateDoesNotExist: sitemap.xml
"GET /sitemap.xml HTTP/1.1" 500 87764
Internal Server Error: /sitemap.xml
Traceback (most recent call last):
  File "C:\Users\asati\AppData\Roaming\Python\Python313\site-packages\django\core\handlers\exception.py", line 55, in inner
    response = get_response(request)
  File "C:\Users\asati\AppData\Roaming\Python\Python313\site-packages\django\core\handlers\base.py", line 220, in _get_response
    response = response.render()
  File "C:\Users\asati\AppData\Roaming\Python\Python313\site-packages\django\template\response.py", line 114, in render
    self.content = self.rendered_content
                   ^^^^^^^^^^^^^^^^^^^^^
  File "C:\Users\asati\AppData\Roaming\Python\Python313\site-packages\django\template\response.py", line 90, in rendered_content
    template = self.resolve_template(self.template_name)
  File "C:\Users\asati\AppData\Roaming\Python\Python313\site-packages\django\template\response.py", line 74, in resolve_template
    return get_template(template, using=self.using)
  File "C:\Users\asati\AppData\Roaming\Python\Python313\site-packages\django\template\loader.py", line 19, in get_template
    raise TemplateDoesNotExist(template_name, chain=chain)
django.template.exceptions.TemplateDoesNotExist: sitemap.xml
"GET /sitemap.xml HTTP/1.1" 500 87764
Internal Server Error: /sitemap.xml
Traceback (most recent call last):
  File "C:\Users\asati\AppData\Roaming\Python\Python313\site-packages\django\core\handlers\exception.py", line 55, in inner
    response = get_response(request)
  File "C:\Users\asati\AppData\Roaming\Python\Python313\site-packages\django\core\handlers\base.py", line 220, in _get_response
    response = response.render()
  File "C:\Users\asati\AppData\Roaming\Python\Python313\site-packages\django\template\response.py", line 114, in render
    self.content = self.rendered_content
                   ^^^^^^^^^^^^^^^^^^^^^
  File "C:\Users\asati\AppData\Roaming\Python\Python313\site-packages\django\template\response.py", line 90, in rendered_content
    template = self.resolve_template(self.template_name)
  File "C:\Users\asati\AppData\Roaming\Python\Python313\site-packages\django\template\response.py", line 74, in resolve_template
    return get_template(template, using=self.using)
  File "C:\Users\asati\AppData\Roaming\Python\Python313\site-packages\django\template\loader.py", line 19, in get_template
    raise TemplateDoesNotExist(template_name, chain=chain)
django.template.exceptions.TemplateDoesNotExist: sitemap.xml
"GET /sitemap.xml HTTP/1.1" 500 87764
Internal Server Error: /sitemap.xml
Traceback (most recent call last):
  File "C:\Users\asati\AppData\Roaming\Python\Python313\site-packages\django\template\defaulttags.py", line 1035, in find_library
    return parser.libraries[name]
           ~~~~~~~~~~~~~~~~^^^^^^
KeyError: 'sitemap_tags'

During handling of the above exception, another exception occurred:

Traceback (most recent call last):
  File "C:\Users\asati\AppData\Roaming\Python\Python313\site-packages\django\core\handlers\exception.py", line 55, in inner
    response = get_response(request)
  File "C:\Users\asati\AppData\Roaming\Python\Python313\site-packages\django\core\handlers\base.py", line 220, in _get_response
    response = response.render()
  File "C:\Users\asati\AppData\Roaming\Python\Python313\site-packages\django\template\response.py", line 114, in render
    self.content = self.rendered_content
                   ^^^^^^^^^^^^^^^^^^^^^
  File "C:\Users\asati\AppData\Roaming\Python\Python313\site-packages\django\template\response.py", line 90, in rendered_content
    template = self.resolve_template(self.template_name)
  File "C:\Users\asati\AppData\Roaming\Python\Python313\site-packages\django\template\response.py", line 74, in resolve_template
    return get_template(template, using=self.using)
  File "C:\Users\asati\AppData\Roaming\Python\Python313\site-packages\django\template\loader.py", line 15, in get_template
    return engine.get_template(template_name)
           ~~~~~~~~~~~~~~~~~~~^^^^^^^^^^^^^^^
  File "C:\Users\asati\AppData\Roaming\Python\Python313\site-packages\django\template\backends\django.py", line 79, in get_template
    return Template(self.engine.get_template(template_name), self)
                    ~~~~~~~~~~~~~~~~~~~~~~~~^^^^^^^^^^^^^^^
  File "C:\Users\asati\AppData\Roaming\Python\Python313\site-packages\django\template\engine.py", line 177, in get_template
    template, origin = self.find_template(template_name)
                       ~~~~~~~~~~~~~~~~~~^^^^^^^^^^^^^^^
  File "C:\Users\asati\AppData\Roaming\Python\Python313\site-packages\django\template\engine.py", line 159, in find_template
    template = loader.get_template(name, skip=skip)
  File "C:\Users\asati\AppData\Roaming\Python\Python313\site-packages\django\template\loaders\cached.py", line 57, in get_template
    template = super().get_template(template_name, skip)
  File "C:\Users\asati\AppData\Roaming\Python\Python313\site-packages\django\template\loaders\base.py", line 28, in get_template
    return Template(
        contents,
    ...<2 lines>...
        self.engine,
    )
  File "C:\Users\asati\AppData\Roaming\Python\Python313\site-packages\django\template\base.py", line 154, in __init__
    self.nodelist = self.compile_nodelist()
                    ~~~~~~~~~~~~~~~~~~~~~^^
  File "C:\Users\asati\AppData\Roaming\Python\Python313\site-packages\django\template\base.py", line 196, in compile_nodelist
    nodelist = parser.parse()
  File "C:\Users\asati\AppData\Roaming\Python\Python313\site-packages\django\template\base.py", line 518, in parse
    raise self.error(token, e)
  File "C:\Users\asati\AppData\Roaming\Python\Python313\site-packages\django\template\base.py", line 516, in parse
    compiled_result = compile_func(self, token)
  File "C:\Users\asati\AppData\Roaming\Python\Python313\site-packages\django\template\defaulttags.py", line 1097, in load
    lib = find_library(parser, name)
  File "C:\Users\asati\AppData\Roaming\Python\Python313\site-packages\django\template\defaulttags.py", line 1037, in find_library
    raise TemplateSyntaxError(
    ...<5 lines>...
    )
django.template.exceptions.TemplateSyntaxError: 'sitemap_tags' is not a registered tag library. Must be one of:
admin_list
admin_modify
admin_urls
cache
i18n
l10n
log
static
tz
"GET /sitemap.xml HTTP/1.1" 500 152957
Internal Server Error: /blogs/
Traceback (most recent call last):
  File "C:\Users\asati\AppData\Roaming\Python\Python313\site-packages\django\core\handlers\exception.py", line 55, in inner
    response = get_response(request)
  File "C:\Users\asati\AppData\Roaming\Python\Python313\site-packages\django\core\handlers\base.py", line 197, in _get_response
    response = wrapped_callback(request, *callback_args, **callback_kwargs)
  File "C:\Users\asati\OneDrive\Desktop\Live Projects\Type2Test\Type2Speed\typing_app\views.py", line 535, in blog_list
    return render(request, 'blog/blog_list.html', {'blogs': blogs})
  File "C:\Users\asati\AppData\Roaming\Python\Python313\site-packages\django\shortcuts.py", line 25, in render
    content = loader.render_to_string(template_name, context, request, using=using)
  File "C:\Users\asati\AppData\Roaming\Python\Python313\site-packages\django\template\loader.py", line 61, in render_to_string
    template = get_template(template_name, using=using)
  File "C:\Users\asati\AppData\Roaming\Python\Python313\site-packages\django\template\loader.py", line 19, in get_template
    raise TemplateDoesNotExist(template_name, chain=chain)
django.template.exceptions.TemplateDoesNotExist: blog/blog_list.html
"GET /blogs/ HTTP/1.1" 500 89889
Internal Server Error: /blogs/
Traceback (most recent call last):
  File "C:\Users\asati\AppData\Roaming\Python\Python313\site-packages\django\core\handlers\exception.py", line 55, in inner
    response = get_response(request)
  File "C:\Users\asati\AppData\Roaming\Python\Python313\site-packages\django\core\handlers\base.py", line 197, in _get_response
    response = wrapped_callback(request, *callback_args, **callback_kwargs)
  File "C:\Users\asati\OneDrive\Desktop\Live Projects\Type2Test\Type2Speed\typing_app\views.py", line 535, in blog_list
    return render(request, 'blogs/blog_list.html', {'blogs': blogs})
  File "C:\Users\asati\AppData\Roaming\Python\Python313\site-packages\django\shortcuts.py", line 25, in render
    content = loader.render_to_string(template_name, context, request, using=using)
  File "C:\Users\asati\AppData\Roaming\Python\Python313\site-packages\django\template\loader.py", line 61, in render_to_string
    template = get_template(template_name, using=using)
  File "C:\Users\asati\AppData\Roaming\Python\Python313\site-packages\django\template\loader.py", line 19, in get_template
    raise TemplateDoesNotExist(template_name, chain=chain)
django.template.exceptions.TemplateDoesNotExist: blogs/blog_list.html
"GET /blogs/ HTTP/1.1" 500 90049
Internal Server Error: /blogs/
Traceback (most recent call last):
  File "C:\Users\asati\AppData\Roaming\Python\Python313\site-packages\django\core\handlers\exception.py", line 55, in inner
    response = get_response(request)
  File "C:\Users\asati\AppData\Roaming\Python\Python313\site-packages\django\core\handlers\base.py", line 197, in _get_response
    response = wrapped_callback(request, *callback_args, **callback_kwargs)
  File "C:\Users\asati\OneDrive\Desktop\Live Projects\Type2Test\Type2Speed\typing_app\views.py", line 535, in blog_list
    return render(request, 'blogs/blog_list.html', {'blogs': blogs})
  File "C:\Users\asati\AppData\Roaming\Python\Python313\site-packages\django\shortcuts.py", line 25, in render
    content = loader.render_to_string(template_name, context, request, using=using)
  File "C:\Users\asati\AppData\Roaming\Python\Python313\site-packages\django\template\loader.py", line 62, in render_to_string
    return template.render(context, request)
           ~~~~~~~~~~~~~~~^^^^^^^^^^^^^^^^^^
  File "C:\Users\asati\AppData\Roaming\Python\Python313\site-packages\django\template\backends\django.py", line 107, in render
    return self.template.render(context)
           ~~~~~~~~~~~~~~~~~~~~^^^^^^^^^
  File "C:\Users\asati\AppData\Roaming\Python\Python313\site-packages\django\template\base.py", line 171, in render
    return self._render(context)
           ~~~~~~~~~~~~^^^^^^^^^
  File "C:\Users\asati\AppData\Roaming\Python\Python313\site-packages\django\template\base.py", line 163, in _render
    return self.nodelist.render(context)
           ~~~~~~~~~~~~~~~~~~~~^^^^^^^^^
  File "C:\Users\asati\AppData\Roaming\Python\Python313\site-packages\django\template\base.py", line 1008, in render
    return SafeString("".join([node.render_annotated(context) for node in self]))
                               ~~~~~~~~~~~~~~~~~~~~~^^^^^^^^^
  File "C:\Users\asati\AppData\Roaming\Python\Python313\site-packages\django\template\base.py", line 969, in render_annotated
    return self.render(context)
           ~~~~~~~~~~~^^^^^^^^^
  File "C:\Users\asati\AppData\Roaming\Python\Python313\site-packages\django\template\loader_tags.py", line 159, in render
    return compiled_parent._render(context)
           ~~~~~~~~~~~~~~~~~~~~~~~^^^^^^^^^
  File "C:\Users\asati\AppData\Roaming\Python\Python313\site-packages\django\template\base.py", line 163, in _render
    return self.nodelist.render(context)
           ~~~~~~~~~~~~~~~~~~~~^^^^^^^^^
  File "C:\Users\asati\AppData\Roaming\Python\Python313\site-packages\django\template\base.py", line 1008, in render
    return SafeString("".join([node.render_annotated(context) for node in self]))
                               ~~~~~~~~~~~~~~~~~~~~~^^^^^^^^^
  File "C:\Users\asati\AppData\Roaming\Python\Python313\site-packages\django\template\base.py", line 969, in render_annotated
    return self.render(context)
           ~~~~~~~~~~~^^^^^^^^^
  File "C:\Users\asati\AppData\Roaming\Python\Python313\site-packages\django\template\loader_tags.py", line 65, in render
    result = block.nodelist.render(context)
  File "C:\Users\asati\AppData\Roaming\Python\Python313\site-packages\django\template\base.py", line 1008, in render
    return SafeString("".join([node.render_annotated(context) for node in self]))
                               ~~~~~~~~~~~~~~~~~~~~~^^^^^^^^^
  File "C:\Users\asati\AppData\Roaming\Python\Python313\site-packages\django\template\base.py", line 969, in render_annotated
    return self.render(context)
           ~~~~~~~~~~~^^^^^^^^^
  File "C:\Users\asati\AppData\Roaming\Python\Python313\site-packages\django\template\defaulttags.py", line 243, in render
    nodelist.append(node.render_annotated(context))
                    ~~~~~~~~~~~~~~~~~~~~~^^^^^^^^^
  File "C:\Users\asati\AppData\Roaming\Python\Python313\site-packages\django\template\base.py", line 969, in render_annotated
    return self.render(context)
           ~~~~~~~~~~~^^^^^^^^^
  File "C:\Users\asati\AppData\Roaming\Python\Python313\site-packages\django\template\defaulttags.py", line 480, in render
    url = reverse(view_name, args=args, kwargs=kwargs, current_app=current_app)
  File "C:\Users\asati\AppData\Roaming\Python\Python313\site-packages\django\urls\base.py", line 88, in reverse
    return resolver._reverse_with_prefix(view, prefix, *args, **kwargs)
           ~~~~~~~~~~~~~~~~~~~~~~~~~~~~~^^^^^^^^^^^^^^^^^^^^^^^^^^^^^^^
  File "C:\Users\asati\AppData\Roaming\Python\Python313\site-packages\django\urls\resolvers.py", line 831, in _reverse_with_prefix
    raise NoReverseMatch(msg)
django.urls.exceptions.NoReverseMatch: Reverse for 'blog_detail' not found. 'blog_detail' is not a valid view function or pattern name.
"GET /blogs/ HTTP/1.1" 500 173266
Internal Server Error: /blogs/
Traceback (most recent call last):
  File "C:\Users\asati\AppData\Roaming\Python\Python313\site-packages\django\core\handlers\exception.py", line 55, in inner
    response = get_response(request)
  File "C:\Users\asati\AppData\Roaming\Python\Python313\site-packages\django\core\handlers\base.py", line 197, in _get_response
    response = wrapped_callback(request, *callback_args, **callback_kwargs)
  File "C:\Users\asati\OneDrive\Desktop\Live Projects\Type2Test\Type2Speed\typing_app\views.py", line 535, in blog_list
    return render(request, 'blogs/blog_list.html', {'blogs': blogs})
  File "C:\Users\asati\AppData\Roaming\Python\Python313\site-packages\django\shortcuts.py", line 25, in render
    content = loader.render_to_string(template_name, context, request, using=using)
  File "C:\Users\asati\AppData\Roaming\Python\Python313\site-packages\django\template\loader.py", line 62, in render_to_string
    return template.render(context, request)
           ~~~~~~~~~~~~~~~^^^^^^^^^^^^^^^^^^
  File "C:\Users\asati\AppData\Roaming\Python\Python313\site-packages\django\template\backends\django.py", line 107, in render
    return self.template.render(context)
           ~~~~~~~~~~~~~~~~~~~~^^^^^^^^^
  File "C:\Users\asati\AppData\Roaming\Python\Python313\site-packages\django\template\base.py", line 171, in render
    return self._render(context)
           ~~~~~~~~~~~~^^^^^^^^^
  File "C:\Users\asati\AppData\Roaming\Python\Python313\site-packages\django\template\base.py", line 163, in _render
    return self.nodelist.render(context)
           ~~~~~~~~~~~~~~~~~~~~^^^^^^^^^
  File "C:\Users\asati\AppData\Roaming\Python\Python313\site-packages\django\template\base.py", line 1008, in render
    return SafeString("".join([node.render_annotated(context) for node in self]))
                               ~~~~~~~~~~~~~~~~~~~~~^^^^^^^^^
  File "C:\Users\asati\AppData\Roaming\Python\Python313\site-packages\django\template\base.py", line 969, in render_annotated
    return self.render(context)
           ~~~~~~~~~~~^^^^^^^^^
  File "C:\Users\asati\AppData\Roaming\Python\Python313\site-packages\django\template\loader_tags.py", line 159, in render
    return compiled_parent._render(context)
           ~~~~~~~~~~~~~~~~~~~~~~~^^^^^^^^^
  File "C:\Users\asati\AppData\Roaming\Python\Python313\site-packages\django\template\base.py", line 163, in _render
    return self.nodelist.render(context)
           ~~~~~~~~~~~~~~~~~~~~^^^^^^^^^
  File "C:\Users\asati\AppData\Roaming\Python\Python313\site-packages\django\template\base.py", line 1008, in render
    return SafeString("".join([node.render_annotated(context) for node in self]))
                               ~~~~~~~~~~~~~~~~~~~~~^^^^^^^^^
  File "C:\Users\asati\AppData\Roaming\Python\Python313\site-packages\django\template\base.py", line 969, in render_annotated
    return self.render(context)
           ~~~~~~~~~~~^^^^^^^^^
  File "C:\Users\asati\AppData\Roaming\Python\Python313\site-packages\django\template\loader_tags.py", line 65, in render
    result = block.nodelist.render(context)
  File "C:\Users\asati\AppData\Roaming\Python\Python313\site-packages\django\template\base.py", line 1008, in render
    return SafeString("".join([node.render_annotated(context) for node in self]))
                               ~~~~~~~~~~~~~~~~~~~~~^^^^^^^^^
  File "C:\Users\asati\AppData\Roaming\Python\Python313\site-packages\django\template\base.py", line 969, in render_annotated
    return self.render(context)
           ~~~~~~~~~~~^^^^^^^^^
  File "C:\Users\asati\AppData\Roaming\Python\Python313\site-packages\django\template\defaulttags.py", line 243, in render
    nodelist.append(node.render_annotated(context))
                    ~~~~~~~~~~~~~~~~~~~~~^^^^^^^^^
  File "C:\Users\asati\AppData\Roaming\Python\Python313\site-packages\django\template\base.py", line 969, in render_annotated
    return self.render(context)
           ~~~~~~~~~~~^^^^^^^^^
  File "C:\Users\asati\AppData\Roaming\Python\Python313\site-packages\django\template\defaulttags.py", line 480, in render
    url = reverse(view_name, args=args, kwargs=kwargs, current_app=current_app)
  File "C:\Users\asati\AppData\Roaming\Python\Python313\site-packages\django\urls\base.py", line 88, in reverse
    return resolver._reverse_with_prefix(view, prefix, *args, **kwargs)
           ~~~~~~~~~~~~~~~~~~~~~~~~~~~~~^^^^^^^^^^^^^^^^^^^^^^^^^^^^^^^
  File "C:\Users\asati\AppData\Roaming\Python\Python313\site-packages\django\urls\resolvers.py", line 831, in _reverse_with_prefix
    raise NoReverseMatch(msg)
django.urls.exceptions.NoReverseMatch: Reverse for 'blog-detail' with keyword arguments '{'slug': ''}' not found. 1 pattern(s) tried: ['blog/(?P<slug>[-a-zA-Z0-9_]+)/\\Z']
"GET /blogs/ HTTP/1.1" 500 176800
Internal Server Error: /blogs/
Traceback (most recent call last):
  File "C:\Users\asati\AppData\Roaming\Python\Python313\site-packages\django\core\handlers\exception.py", line 55, in inner
    response = get_response(request)
  File "C:\Users\asati\AppData\Roaming\Python\Python313\site-packages\django\core\handlers\base.py", line 197, in _get_response
    response = wrapped_callback(request, *callback_args, **callback_kwargs)
  File "C:\Users\asati\OneDrive\Desktop\Live Projects\Type2Test\Type2Speed\typing_app\views.py", line 535, in blog_list
    return render(request, 'blogs/blog_list.html', {'blogs': blogs})
  File "C:\Users\asati\AppData\Roaming\Python\Python313\site-packages\django\shortcuts.py", line 25, in render
    content = loader.render_to_string(template_name, context, request, using=using)
  File "C:\Users\asati\AppData\Roaming\Python\Python313\site-packages\django\template\loader.py", line 62, in render_to_string
    return template.render(context, request)
           ~~~~~~~~~~~~~~~^^^^^^^^^^^^^^^^^^
  File "C:\Users\asati\AppData\Roaming\Python\Python313\site-packages\django\template\backends\django.py", line 107, in render
    return self.template.render(context)
           ~~~~~~~~~~~~~~~~~~~~^^^^^^^^^
  File "C:\Users\asati\AppData\Roaming\Python\Python313\site-packages\django\template\base.py", line 171, in render
    return self._render(context)
           ~~~~~~~~~~~~^^^^^^^^^
  File "C:\Users\asati\AppData\Roaming\Python\Python313\site-packages\django\template\base.py", line 163, in _render
    return self.nodelist.render(context)
           ~~~~~~~~~~~~~~~~~~~~^^^^^^^^^
  File "C:\Users\asati\AppData\Roaming\Python\Python313\site-packages\django\template\base.py", line 1008, in render
    return SafeString("".join([node.render_annotated(context) for node in self]))
                               ~~~~~~~~~~~~~~~~~~~~~^^^^^^^^^
  File "C:\Users\asati\AppData\Roaming\Python\Python313\site-packages\django\template\base.py", line 969, in render_annotated
    return self.render(context)
           ~~~~~~~~~~~^^^^^^^^^
  File "C:\Users\asati\AppData\Roaming\Python\Python313\site-packages\django\template\loader_tags.py", line 159, in render
    return compiled_parent._render(context)
           ~~~~~~~~~~~~~~~~~~~~~~~^^^^^^^^^
  File "C:\Users\asati\AppData\Roaming\Python\Python313\site-packages\django\template\base.py", line 163, in _render
    return self.nodelist.render(context)
           ~~~~~~~~~~~~~~~~~~~~^^^^^^^^^
  File "C:\Users\asati\AppData\Roaming\Python\Python313\site-packages\django\template\base.py", line 1008, in render
    return SafeString("".join([node.render_annotated(context) for node in self]))
                               ~~~~~~~~~~~~~~~~~~~~~^^^^^^^^^
  File "C:\Users\asati\AppData\Roaming\Python\Python313\site-packages\django\template\base.py", line 969, in render_annotated
    return self.render(context)
           ~~~~~~~~~~~^^^^^^^^^
  File "C:\Users\asati\AppData\Roaming\Python\Python313\site-packages\django\template\loader_tags.py", line 65, in render
    result = block.nodelist.render(context)
  File "C:\Users\asati\AppData\Roaming\Python\Python313\site-packages\django\template\base.py", line 1008, in render
    return SafeString("".join([node.render_annotated(context) for node in self]))
                               ~~~~~~~~~~~~~~~~~~~~~^^^^^^^^^
  File "C:\Users\asati\AppData\Roaming\Python\Python313\site-packages\django\template\base.py", line 969, in render_annotated
    return self.render(context)
           ~~~~~~~~~~~^^^^^^^^^
  File "C:\Users\asati\AppData\Roaming\Python\Python313\site-packages\django\template\defaulttags.py", line 243, in render
    nodelist.append(node.render_annotated(context))
                    ~~~~~~~~~~~~~~~~~~~~~^^^^^^^^^
  File "C:\Users\asati\AppData\Roaming\Python\Python313\site-packages\django\template\base.py", line 969, in render_annotated
    return self.render(context)
           ~~~~~~~~~~~^^^^^^^^^
  File "C:\Users\asati\AppData\Roaming\Python\Python313\site-packages\django\template\defaulttags.py", line 480, in render
    url = reverse(view_name, args=args, kwargs=kwargs, current_app=current_app)
  File "C:\Users\asati\AppData\Roaming\Python\Python313\site-packages\django\urls\base.py", line 88, in reverse
    return resolver._reverse_with_prefix(view, prefix, *args, **kwargs)
           ~~~~~~~~~~~~~~~~~~~~~~~~~~~~~^^^^^^^^^^^^^^^^^^^^^^^^^^^^^^^
  File "C:\Users\asati\AppData\Roaming\Python\Python313\site-packages\django\urls\resolvers.py", line 831, in _reverse_with_prefix
    raise NoReverseMatch(msg)
django.urls.exceptions.NoReverseMatch: Reverse for 'blog-detail' with keyword arguments '{'slug': ''}' not found. 1 pattern(s) tried: ['blog/(?P<slug>[-a-zA-Z0-9_]+)/\\Z']
"GET /blogs/ HTTP/1.1" 500 176663
Internal Server Error: /admin/typing_app/blog/add/
Traceback (most recent call last):
  File "C:\Users\asati\AppData\Roaming\Python\Python313\site-packages\django\db\backends\utils.py", line 105, in _execute
    return self.cursor.execute(sql, params)
           ~~~~~~~~~~~~~~~~~~~^^^^^^^^^^^^^
psycopg2.errors.StringDataRightTruncation: value too long for type character varying(50)


The above exception was the direct cause of the following exception:

Traceback (most recent call last):
  File "C:\Users\asati\AppData\Roaming\Python\Python313\site-packages\django\core\handlers\exception.py", line 55, in inner
    response = get_response(request)
  File "C:\Users\asati\AppData\Roaming\Python\Python313\site-packages\django\core\handlers\base.py", line 197, in _get_response
    response = wrapped_callback(request, *callback_args, **callback_kwargs)
  File "C:\Users\asati\AppData\Roaming\Python\Python313\site-packages\django\contrib\admin\options.py", line 718, in wrapper
    return self.admin_site.admin_view(view)(*args, **kwargs)
           ~~~~~~~~~~~~~~~~~~~~~~~~~~~~~~~~^^^^^^^^^^^^^^^^^
  File "C:\Users\asati\AppData\Roaming\Python\Python313\site-packages\django\utils\decorators.py", line 188, in _view_wrapper
    result = _process_exception(request, e)
  File "C:\Users\asati\AppData\Roaming\Python\Python313\site-packages\django\utils\decorators.py", line 186, in _view_wrapper
    response = view_func(request, *args, **kwargs)
  File "C:\Users\asati\AppData\Roaming\Python\Python313\site-packages\django\views\decorators\cache.py", line 80, in _view_wrapper
    response = view_func(request, *args, **kwargs)
  File "C:\Users\asati\AppData\Roaming\Python\Python313\site-packages\django\contrib\admin\sites.py", line 241, in inner
    return view(request, *args, **kwargs)
  File "C:\Users\asati\AppData\Roaming\Python\Python313\site-packages\django\contrib\admin\options.py", line 1961, in add_view
    return self.changeform_view(request, None, form_url, extra_context)
           ~~~~~~~~~~~~~~~~~~~~^^^^^^^^^^^^^^^^^^^^^^^^^^^^^^^^^^^^^^^^
  File "C:\Users\asati\AppData\Roaming\Python\Python313\site-packages\django\utils\decorators.py", line 48, in _wrapper
    return bound_method(*args, **kwargs)
  File "C:\Users\asati\AppData\Roaming\Python\Python313\site-packages\django\utils\decorators.py", line 188, in _view_wrapper
    result = _process_exception(request, e)
  File "C:\Users\asati\AppData\Roaming\Python\Python313\site-packages\django\utils\decorators.py", line 186, in _view_wrapper
    response = view_func(request, *args, **kwargs)
  File "C:\Users\asati\AppData\Roaming\Python\Python313\site-packages\django\contrib\admin\options.py", line 1820, in changeform_view
    return self._changeform_view(request, object_id, form_url, extra_context)
           ~~~~~~~~~~~~~~~~~~~~~^^^^^^^^^^^^^^^^^^^^^^^^^^^^^^^^^^^^^^^^^^^^^
  File "C:\Users\asati\AppData\Roaming\Python\Python313\site-packages\django\contrib\admin\options.py", line 1871, in _changeform_view
    self.save_model(request, new_object, form, not add)
    ~~~~~~~~~~~~~~~^^^^^^^^^^^^^^^^^^^^^^^^^^^^^^^^^^^^
  File "C:\Users\asati\AppData\Roaming\Python\Python313\site-packages\django\contrib\admin\options.py", line 1294, in save_model
    obj.save()
    ~~~~~~~~^^
  File "C:\Users\asati\OneDrive\Desktop\Live Projects\Type2Test\Type2Speed\typing_app\models.py", line 134, in save
    super().save(*args, **kwargs)
    ~~~~~~~~~~~~^^^^^^^^^^^^^^^^^
  File "C:\Users\asati\AppData\Roaming\Python\Python313\site-packages\django\db\models\base.py", line 892, in save
    self.save_base(
    ~~~~~~~~~~~~~~^
        using=using,
        ^^^^^^^^^^^^
    ...<2 lines>...
        update_fields=update_fields,
        ^^^^^^^^^^^^^^^^^^^^^^^^^^^^
    )
    ^
  File "C:\Users\asati\AppData\Roaming\Python\Python313\site-packages\django\db\models\base.py", line 998, in save_base
    updated = self._save_table(
        raw,
    ...<4 lines>...
        update_fields,
    )
  File "C:\Users\asati\AppData\Roaming\Python\Python313\site-packages\django\db\models\base.py", line 1161, in _save_table
    results = self._do_insert(
        cls._base_manager, using, fields, returning_fields, raw
    )
  File "C:\Users\asati\AppData\Roaming\Python\Python313\site-packages\django\db\models\base.py", line 1202, in _do_insert
    return manager._insert(
           ~~~~~~~~~~~~~~~^
        [self],
        ^^^^^^^
    ...<3 lines>...
        raw=raw,
        ^^^^^^^^
    )
    ^
  File "C:\Users\asati\AppData\Roaming\Python\Python313\site-packages\django\db\models\manager.py", line 87, in manager_method
    return getattr(self.get_queryset(), name)(*args, **kwargs)
           ~~~~~~~~~~~~~~~~~~~~~~~~~~~~~~~~~~^^^^^^^^^^^^^^^^^
  File "C:\Users\asati\AppData\Roaming\Python\Python313\site-packages\django\db\models\query.py", line 1847, in _insert
    return query.get_compiler(using=using).execute_sql(returning_fields)
           ~~~~~~~~~~~~~~~~~~~~~~~~~~~~~~~~~~~~~~~~~~~^^^^^^^^^^^^^^^^^^
  File "C:\Users\asati\AppData\Roaming\Python\Python313\site-packages\django\db\models\sql\compiler.py", line 1836, in execute_sql
    cursor.execute(sql, params)
    ~~~~~~~~~~~~~~^^^^^^^^^^^^^
  File "C:\Users\asati\AppData\Roaming\Python\Python313\site-packages\django\db\backends\utils.py", line 122, in execute
    return super().execute(sql, params)
           ~~~~~~~~~~~~~~~^^^^^^^^^^^^^
  File "C:\Users\asati\AppData\Roaming\Python\Python313\site-packages\django\db\backends\utils.py", line 79, in execute
    return self._execute_with_wrappers(
           ~~~~~~~~~~~~~~~~~~~~~~~~~~~^
        sql, params, many=False, executor=self._execute
        ^^^^^^^^^^^^^^^^^^^^^^^^^^^^^^^^^^^^^^^^^^^^^^^
    )
    ^
  File "C:\Users\asati\AppData\Roaming\Python\Python313\site-packages\django\db\backends\utils.py", line 92, in _execute_with_wrappers
    return executor(sql, params, many, context)
  File "C:\Users\asati\AppData\Roaming\Python\Python313\site-packages\django\db\backends\utils.py", line 100, in _execute
    with self.db.wrap_database_errors:
         ^^^^^^^^^^^^^^^^^^^^^^^^^^^^
  File "C:\Users\asati\AppData\Roaming\Python\Python313\site-packages\django\db\utils.py", line 91, in __exit__
    raise dj_exc_value.with_traceback(traceback) from exc_value
  File "C:\Users\asati\AppData\Roaming\Python\Python313\site-packages\django\db\backends\utils.py", line 105, in _execute
    return self.cursor.execute(sql, params)
           ~~~~~~~~~~~~~~~~~~~^^^^^^^^^^^^^
django.db.utils.DataError: value too long for type character varying(50)

"POST /admin/typing_app/blog/add/ HTTP/1.1" 500 235068
Internal Server Error: /admin/typing_app/blog/add/
Traceback (most recent call last):
  File "C:\Users\asati\AppData\Roaming\Python\Python313\site-packages\django\db\backends\utils.py", line 105, in _execute
    return self.cursor.execute(sql, params)
           ~~~~~~~~~~~~~~~~~~~^^^^^^^^^^^^^
psycopg2.errors.StringDataRightTruncation: value too long for type character varying(50)


The above exception was the direct cause of the following exception:

Traceback (most recent call last):
  File "C:\Users\asati\AppData\Roaming\Python\Python313\site-packages\django\core\handlers\exception.py", line 55, in inner
    response = get_response(request)
  File "C:\Users\asati\AppData\Roaming\Python\Python313\site-packages\django\core\handlers\base.py", line 197, in _get_response
    response = wrapped_callback(request, *callback_args, **callback_kwargs)
  File "C:\Users\asati\AppData\Roaming\Python\Python313\site-packages\django\contrib\admin\options.py", line 718, in wrapper
    return self.admin_site.admin_view(view)(*args, **kwargs)
           ~~~~~~~~~~~~~~~~~~~~~~~~~~~~~~~~^^^^^^^^^^^^^^^^^
  File "C:\Users\asati\AppData\Roaming\Python\Python313\site-packages\django\utils\decorators.py", line 188, in _view_wrapper
    result = _process_exception(request, e)
  File "C:\Users\asati\AppData\Roaming\Python\Python313\site-packages\django\utils\decorators.py", line 186, in _view_wrapper
    response = view_func(request, *args, **kwargs)
  File "C:\Users\asati\AppData\Roaming\Python\Python313\site-packages\django\views\decorators\cache.py", line 80, in _view_wrapper
    response = view_func(request, *args, **kwargs)
  File "C:\Users\asati\AppData\Roaming\Python\Python313\site-packages\django\contrib\admin\sites.py", line 241, in inner
    return view(request, *args, **kwargs)
  File "C:\Users\asati\AppData\Roaming\Python\Python313\site-packages\django\contrib\admin\options.py", line 1961, in add_view
    return self.changeform_view(request, None, form_url, extra_context)
           ~~~~~~~~~~~~~~~~~~~~^^^^^^^^^^^^^^^^^^^^^^^^^^^^^^^^^^^^^^^^
  File "C:\Users\asati\AppData\Roaming\Python\Python313\site-packages\django\utils\decorators.py", line 48, in _wrapper
    return bound_method(*args, **kwargs)
  File "C:\Users\asati\AppData\Roaming\Python\Python313\site-packages\django\utils\decorators.py", line 188, in _view_wrapper
    result = _process_exception(request, e)
  File "C:\Users\asati\AppData\Roaming\Python\Python313\site-packages\django\utils\decorators.py", line 186, in _view_wrapper
    response = view_func(request, *args, **kwargs)
  File "C:\Users\asati\AppData\Roaming\Python\Python313\site-packages\django\contrib\admin\options.py", line 1820, in changeform_view
    return self._changeform_view(request, object_id, form_url, extra_context)
           ~~~~~~~~~~~~~~~~~~~~~^^^^^^^^^^^^^^^^^^^^^^^^^^^^^^^^^^^^^^^^^^^^^
  File "C:\Users\asati\AppData\Roaming\Python\Python313\site-packages\django\contrib\admin\options.py", line 1871, in _changeform_view
    self.save_model(request, new_object, form, not add)
    ~~~~~~~~~~~~~~~^^^^^^^^^^^^^^^^^^^^^^^^^^^^^^^^^^^^
  File "C:\Users\asati\AppData\Roaming\Python\Python313\site-packages\django\contrib\admin\options.py", line 1294, in save_model
    obj.save()
    ~~~~~~~~^^
  File "C:\Users\asati\OneDrive\Desktop\Live Projects\Type2Test\Type2Speed\typing_app\models.py", line 134, in save
    super().save(*args, **kwargs)
    ~~~~~~~~~~~~^^^^^^^^^^^^^^^^^
  File "C:\Users\asati\AppData\Roaming\Python\Python313\site-packages\django\db\models\base.py", line 892, in save
    self.save_base(
    ~~~~~~~~~~~~~~^
        using=using,
        ^^^^^^^^^^^^
    ...<2 lines>...
        update_fields=update_fields,
        ^^^^^^^^^^^^^^^^^^^^^^^^^^^^
    )
    ^
  File "C:\Users\asati\AppData\Roaming\Python\Python313\site-packages\django\db\models\base.py", line 998, in save_base
    updated = self._save_table(
        raw,
    ...<4 lines>...
        update_fields,
    )
  File "C:\Users\asati\AppData\Roaming\Python\Python313\site-packages\django\db\models\base.py", line 1161, in _save_table
    results = self._do_insert(
        cls._base_manager, using, fields, returning_fields, raw
    )
  File "C:\Users\asati\AppData\Roaming\Python\Python313\site-packages\django\db\models\base.py", line 1202, in _do_insert
    return manager._insert(
           ~~~~~~~~~~~~~~~^
        [self],
        ^^^^^^^
    ...<3 lines>...
        raw=raw,
        ^^^^^^^^
    )
    ^
  File "C:\Users\asati\AppData\Roaming\Python\Python313\site-packages\django\db\models\manager.py", line 87, in manager_method
    return getattr(self.get_queryset(), name)(*args, **kwargs)
           ~~~~~~~~~~~~~~~~~~~~~~~~~~~~~~~~~~^^^^^^^^^^^^^^^^^
  File "C:\Users\asati\AppData\Roaming\Python\Python313\site-packages\django\db\models\query.py", line 1847, in _insert
    return query.get_compiler(using=using).execute_sql(returning_fields)
           ~~~~~~~~~~~~~~~~~~~~~~~~~~~~~~~~~~~~~~~~~~~^^^^^^^^^^^^^^^^^^
  File "C:\Users\asati\AppData\Roaming\Python\Python313\site-packages\django\db\models\sql\compiler.py", line 1836, in execute_sql
    cursor.execute(sql, params)
    ~~~~~~~~~~~~~~^^^^^^^^^^^^^
  File "C:\Users\asati\AppData\Roaming\Python\Python313\site-packages\django\db\backends\utils.py", line 122, in execute
    return super().execute(sql, params)
           ~~~~~~~~~~~~~~~^^^^^^^^^^^^^
  File "C:\Users\asati\AppData\Roaming\Python\Python313\site-packages\django\db\backends\utils.py", line 79, in execute
    return self._execute_with_wrappers(
           ~~~~~~~~~~~~~~~~~~~~~~~~~~~^
        sql, params, many=False, executor=self._execute
        ^^^^^^^^^^^^^^^^^^^^^^^^^^^^^^^^^^^^^^^^^^^^^^^
    )
    ^
  File "C:\Users\asati\AppData\Roaming\Python\Python313\site-packages\django\db\backends\utils.py", line 92, in _execute_with_wrappers
    return executor(sql, params, many, context)
  File "C:\Users\asati\AppData\Roaming\Python\Python313\site-packages\django\db\backends\utils.py", line 100, in _execute
    with self.db.wrap_database_errors:
         ^^^^^^^^^^^^^^^^^^^^^^^^^^^^
  File "C:\Users\asati\AppData\Roaming\Python\Python313\site-packages\django\db\utils.py", line 91, in __exit__
    raise dj_exc_value.with_traceback(traceback) from exc_value
  File "C:\Users\asati\AppData\Roaming\Python\Python313\site-packages\django\db\backends\utils.py", line 105, in _execute
    return self.cursor.execute(sql, params)
           ~~~~~~~~~~~~~~~~~~~^^^^^^^^^^^^^
django.db.utils.DataError: value too long for type character varying(50)

"POST /admin/typing_app/blog/add/ HTTP/1.1" 500 235068
Internal Server Error: /admin/typing_app/blog/add/
Traceback (most recent call last):
  File "C:\Users\asati\AppData\Roaming\Python\Python313\site-packages\django\db\backends\utils.py", line 105, in _execute
    return self.cursor.execute(sql, params)
           ~~~~~~~~~~~~~~~~~~~^^^^^^^^^^^^^
psycopg2.errors.StringDataRightTruncation: value too long for type character varying(50)


The above exception was the direct cause of the following exception:

Traceback (most recent call last):
  File "C:\Users\asati\AppData\Roaming\Python\Python313\site-packages\django\core\handlers\exception.py", line 55, in inner
    response = get_response(request)
  File "C:\Users\asati\AppData\Roaming\Python\Python313\site-packages\django\core\handlers\base.py", line 197, in _get_response
    response = wrapped_callback(request, *callback_args, **callback_kwargs)
  File "C:\Users\asati\AppData\Roaming\Python\Python313\site-packages\django\contrib\admin\options.py", line 718, in wrapper
    return self.admin_site.admin_view(view)(*args, **kwargs)
           ~~~~~~~~~~~~~~~~~~~~~~~~~~~~~~~~^^^^^^^^^^^^^^^^^
  File "C:\Users\asati\AppData\Roaming\Python\Python313\site-packages\django\utils\decorators.py", line 188, in _view_wrapper
    result = _process_exception(request, e)
  File "C:\Users\asati\AppData\Roaming\Python\Python313\site-packages\django\utils\decorators.py", line 186, in _view_wrapper
    response = view_func(request, *args, **kwargs)
  File "C:\Users\asati\AppData\Roaming\Python\Python313\site-packages\django\views\decorators\cache.py", line 80, in _view_wrapper
    response = view_func(request, *args, **kwargs)
  File "C:\Users\asati\AppData\Roaming\Python\Python313\site-packages\django\contrib\admin\sites.py", line 241, in inner
    return view(request, *args, **kwargs)
  File "C:\Users\asati\AppData\Roaming\Python\Python313\site-packages\django\contrib\admin\options.py", line 1961, in add_view
    return self.changeform_view(request, None, form_url, extra_context)
           ~~~~~~~~~~~~~~~~~~~~^^^^^^^^^^^^^^^^^^^^^^^^^^^^^^^^^^^^^^^^
  File "C:\Users\asati\AppData\Roaming\Python\Python313\site-packages\django\utils\decorators.py", line 48, in _wrapper
    return bound_method(*args, **kwargs)
  File "C:\Users\asati\AppData\Roaming\Python\Python313\site-packages\django\utils\decorators.py", line 188, in _view_wrapper
    result = _process_exception(request, e)
  File "C:\Users\asati\AppData\Roaming\Python\Python313\site-packages\django\utils\decorators.py", line 186, in _view_wrapper
    response = view_func(request, *args, **kwargs)
  File "C:\Users\asati\AppData\Roaming\Python\Python313\site-packages\django\contrib\admin\options.py", line 1820, in changeform_view
    return self._changeform_view(request, object_id, form_url, extra_context)
           ~~~~~~~~~~~~~~~~~~~~~^^^^^^^^^^^^^^^^^^^^^^^^^^^^^^^^^^^^^^^^^^^^^
  File "C:\Users\asati\AppData\Roaming\Python\Python313\site-packages\django\contrib\admin\options.py", line 1871, in _changeform_view
    self.save_model(request, new_object, form, not add)
    ~~~~~~~~~~~~~~~^^^^^^^^^^^^^^^^^^^^^^^^^^^^^^^^^^^^
  File "C:\Users\asati\AppData\Roaming\Python\Python313\site-packages\django\contrib\admin\options.py", line 1294, in save_model
    obj.save()
    ~~~~~~~~^^
  File "C:\Users\asati\OneDrive\Desktop\Live Projects\Type2Test\Type2Speed\typing_app\models.py", line 134, in save
    super().save(*args, **kwargs)
    ~~~~~~~~~~~~^^^^^^^^^^^^^^^^^
  File "C:\Users\asati\AppData\Roaming\Python\Python313\site-packages\django\db\models\base.py", line 892, in save
    self.save_base(
    ~~~~~~~~~~~~~~^
        using=using,
        ^^^^^^^^^^^^
    ...<2 lines>...
        update_fields=update_fields,
        ^^^^^^^^^^^^^^^^^^^^^^^^^^^^
    )
    ^
  File "C:\Users\asati\AppData\Roaming\Python\Python313\site-packages\django\db\models\base.py", line 998, in save_base
    updated = self._save_table(
        raw,
    ...<4 lines>...
        update_fields,
    )
  File "C:\Users\asati\AppData\Roaming\Python\Python313\site-packages\django\db\models\base.py", line 1161, in _save_table
    results = self._do_insert(
        cls._base_manager, using, fields, returning_fields, raw
    )
  File "C:\Users\asati\AppData\Roaming\Python\Python313\site-packages\django\db\models\base.py", line 1202, in _do_insert
    return manager._insert(
           ~~~~~~~~~~~~~~~^
        [self],
        ^^^^^^^
    ...<3 lines>...
        raw=raw,
        ^^^^^^^^
    )
    ^
  File "C:\Users\asati\AppData\Roaming\Python\Python313\site-packages\django\db\models\manager.py", line 87, in manager_method
    return getattr(self.get_queryset(), name)(*args, **kwargs)
           ~~~~~~~~~~~~~~~~~~~~~~~~~~~~~~~~~~^^^^^^^^^^^^^^^^^
  File "C:\Users\asati\AppData\Roaming\Python\Python313\site-packages\django\db\models\query.py", line 1847, in _insert
    return query.get_compiler(using=using).execute_sql(returning_fields)
           ~~~~~~~~~~~~~~~~~~~~~~~~~~~~~~~~~~~~~~~~~~~^^^^^^^^^^^^^^^^^^
  File "C:\Users\asati\AppData\Roaming\Python\Python313\site-packages\django\db\models\sql\compiler.py", line 1836, in execute_sql
    cursor.execute(sql, params)
    ~~~~~~~~~~~~~~^^^^^^^^^^^^^
  File "C:\Users\asati\AppData\Roaming\Python\Python313\site-packages\django\db\backends\utils.py", line 122, in execute
    return super().execute(sql, params)
           ~~~~~~~~~~~~~~~^^^^^^^^^^^^^
  File "C:\Users\asati\AppData\Roaming\Python\Python313\site-packages\django\db\backends\utils.py", line 79, in execute
    return self._execute_with_wrappers(
           ~~~~~~~~~~~~~~~~~~~~~~~~~~~^
        sql, params, many=False, executor=self._execute
        ^^^^^^^^^^^^^^^^^^^^^^^^^^^^^^^^^^^^^^^^^^^^^^^
    )
    ^
  File "C:\Users\asati\AppData\Roaming\Python\Python313\site-packages\django\db\backends\utils.py", line 92, in _execute_with_wrappers
    return executor(sql, params, many, context)
  File "C:\Users\asati\AppData\Roaming\Python\Python313\site-packages\django\db\backends\utils.py", line 100, in _execute
    with self.db.wrap_database_errors:
         ^^^^^^^^^^^^^^^^^^^^^^^^^^^^
  File "C:\Users\asati\AppData\Roaming\Python\Python313\site-packages\django\db\utils.py", line 91, in __exit__
    raise dj_exc_value.with_traceback(traceback) from exc_value
  File "C:\Users\asati\AppData\Roaming\Python\Python313\site-packages\django\db\backends\utils.py", line 105, in _execute
    return self.cursor.execute(sql, params)
           ~~~~~~~~~~~~~~~~~~~^^^^^^^^^^^^^
django.db.utils.DataError: value too long for type character varying(50)

"POST /admin/typing_app/blog/add/ HTTP/1.1" 500 235068
Internal Server Error: /admin/typing_app/blog/add/
Traceback (most recent call last):
  File "C:\Users\asati\AppData\Roaming\Python\Python313\site-packages\django\db\backends\utils.py", line 105, in _execute
    return self.cursor.execute(sql, params)
           ~~~~~~~~~~~~~~~~~~~^^^^^^^^^^^^^
psycopg2.errors.StringDataRightTruncation: value too long for type character varying(50)


The above exception was the direct cause of the following exception:

Traceback (most recent call last):
  File "C:\Users\asati\AppData\Roaming\Python\Python313\site-packages\django\core\handlers\exception.py", line 55, in inner
    response = get_response(request)
  File "C:\Users\asati\AppData\Roaming\Python\Python313\site-packages\django\core\handlers\base.py", line 197, in _get_response
    response = wrapped_callback(request, *callback_args, **callback_kwargs)
  File "C:\Users\asati\AppData\Roaming\Python\Python313\site-packages\django\contrib\admin\options.py", line 718, in wrapper
    return self.admin_site.admin_view(view)(*args, **kwargs)
           ~~~~~~~~~~~~~~~~~~~~~~~~~~~~~~~~^^^^^^^^^^^^^^^^^
  File "C:\Users\asati\AppData\Roaming\Python\Python313\site-packages\django\utils\decorators.py", line 188, in _view_wrapper
    result = _process_exception(request, e)
  File "C:\Users\asati\AppData\Roaming\Python\Python313\site-packages\django\utils\decorators.py", line 186, in _view_wrapper
    response = view_func(request, *args, **kwargs)
  File "C:\Users\asati\AppData\Roaming\Python\Python313\site-packages\django\views\decorators\cache.py", line 80, in _view_wrapper
    response = view_func(request, *args, **kwargs)
  File "C:\Users\asati\AppData\Roaming\Python\Python313\site-packages\django\contrib\admin\sites.py", line 241, in inner
    return view(request, *args, **kwargs)
  File "C:\Users\asati\AppData\Roaming\Python\Python313\site-packages\django\contrib\admin\options.py", line 1961, in add_view
    return self.changeform_view(request, None, form_url, extra_context)
           ~~~~~~~~~~~~~~~~~~~~^^^^^^^^^^^^^^^^^^^^^^^^^^^^^^^^^^^^^^^^
  File "C:\Users\asati\AppData\Roaming\Python\Python313\site-packages\django\utils\decorators.py", line 48, in _wrapper
    return bound_method(*args, **kwargs)
  File "C:\Users\asati\AppData\Roaming\Python\Python313\site-packages\django\utils\decorators.py", line 188, in _view_wrapper
    result = _process_exception(request, e)
  File "C:\Users\asati\AppData\Roaming\Python\Python313\site-packages\django\utils\decorators.py", line 186, in _view_wrapper
    response = view_func(request, *args, **kwargs)
  File "C:\Users\asati\AppData\Roaming\Python\Python313\site-packages\django\contrib\admin\options.py", line 1820, in changeform_view
    return self._changeform_view(request, object_id, form_url, extra_context)
           ~~~~~~~~~~~~~~~~~~~~~^^^^^^^^^^^^^^^^^^^^^^^^^^^^^^^^^^^^^^^^^^^^^
  File "C:\Users\asati\AppData\Roaming\Python\Python313\site-packages\django\contrib\admin\options.py", line 1871, in _changeform_view
    self.save_model(request, new_object, form, not add)
    ~~~~~~~~~~~~~~~^^^^^^^^^^^^^^^^^^^^^^^^^^^^^^^^^^^^
  File "C:\Users\asati\AppData\Roaming\Python\Python313\site-packages\django\contrib\admin\options.py", line 1294, in save_model
    obj.save()
    ~~~~~~~~^^
  File "C:\Users\asati\OneDrive\Desktop\Live Projects\Type2Test\Type2Speed\typing_app\models.py", line 134, in save
    super().save(*args, **kwargs)
    ~~~~~~~~~~~~^^^^^^^^^^^^^^^^^
  File "C:\Users\asati\AppData\Roaming\Python\Python313\site-packages\django\db\models\base.py", line 892, in save
    self.save_base(
    ~~~~~~~~~~~~~~^
        using=using,
        ^^^^^^^^^^^^
    ...<2 lines>...
        update_fields=update_fields,
        ^^^^^^^^^^^^^^^^^^^^^^^^^^^^
    )
    ^
  File "C:\Users\asati\AppData\Roaming\Python\Python313\site-packages\django\db\models\base.py", line 998, in save_base
    updated = self._save_table(
        raw,
    ...<4 lines>...
        update_fields,
    )
  File "C:\Users\asati\AppData\Roaming\Python\Python313\site-packages\django\db\models\base.py", line 1161, in _save_table
    results = self._do_insert(
        cls._base_manager, using, fields, returning_fields, raw
    )
  File "C:\Users\asati\AppData\Roaming\Python\Python313\site-packages\django\db\models\base.py", line 1202, in _do_insert
    return manager._insert(
           ~~~~~~~~~~~~~~~^
        [self],
        ^^^^^^^
    ...<3 lines>...
        raw=raw,
        ^^^^^^^^
    )
    ^
  File "C:\Users\asati\AppData\Roaming\Python\Python313\site-packages\django\db\models\manager.py", line 87, in manager_method
    return getattr(self.get_queryset(), name)(*args, **kwargs)
           ~~~~~~~~~~~~~~~~~~~~~~~~~~~~~~~~~~^^^^^^^^^^^^^^^^^
  File "C:\Users\asati\AppData\Roaming\Python\Python313\site-packages\django\db\models\query.py", line 1847, in _insert
    return query.get_compiler(using=using).execute_sql(returning_fields)
           ~~~~~~~~~~~~~~~~~~~~~~~~~~~~~~~~~~~~~~~~~~~^^^^^^^^^^^^^^^^^^
  File "C:\Users\asati\AppData\Roaming\Python\Python313\site-packages\django\db\models\sql\compiler.py", line 1836, in execute_sql
    cursor.execute(sql, params)
    ~~~~~~~~~~~~~~^^^^^^^^^^^^^
  File "C:\Users\asati\AppData\Roaming\Python\Python313\site-packages\django\db\backends\utils.py", line 122, in execute
    return super().execute(sql, params)
           ~~~~~~~~~~~~~~~^^^^^^^^^^^^^
  File "C:\Users\asati\AppData\Roaming\Python\Python313\site-packages\django\db\backends\utils.py", line 79, in execute
    return self._execute_with_wrappers(
           ~~~~~~~~~~~~~~~~~~~~~~~~~~~^
        sql, params, many=False, executor=self._execute
        ^^^^^^^^^^^^^^^^^^^^^^^^^^^^^^^^^^^^^^^^^^^^^^^
    )
    ^
  File "C:\Users\asati\AppData\Roaming\Python\Python313\site-packages\django\db\backends\utils.py", line 92, in _execute_with_wrappers
    return executor(sql, params, many, context)
  File "C:\Users\asati\AppData\Roaming\Python\Python313\site-packages\django\db\backends\utils.py", line 100, in _execute
    with self.db.wrap_database_errors:
         ^^^^^^^^^^^^^^^^^^^^^^^^^^^^
  File "C:\Users\asati\AppData\Roaming\Python\Python313\site-packages\django\db\utils.py", line 91, in __exit__
    raise dj_exc_value.with_traceback(traceback) from exc_value
  File "C:\Users\asati\AppData\Roaming\Python\Python313\site-packages\django\db\backends\utils.py", line 105, in _execute
    return self.cursor.execute(sql, params)
           ~~~~~~~~~~~~~~~~~~~^^^^^^^^^^^^^
django.db.utils.DataError: value too long for type character varying(50)

"POST /admin/typing_app/blog/add/ HTTP/1.1" 500 235068
Internal Server Error: /admin/typing_app/blog/add/
Traceback (most recent call last):
  File "C:\Users\asati\AppData\Roaming\Python\Python313\site-packages\django\db\backends\utils.py", line 105, in _execute
    return self.cursor.execute(sql, params)
           ~~~~~~~~~~~~~~~~~~~^^^^^^^^^^^^^
psycopg2.errors.StringDataRightTruncation: value too long for type character varying(50)


The above exception was the direct cause of the following exception:

Traceback (most recent call last):
  File "C:\Users\asati\AppData\Roaming\Python\Python313\site-packages\django\core\handlers\exception.py", line 55, in inner
    response = get_response(request)
  File "C:\Users\asati\AppData\Roaming\Python\Python313\site-packages\django\core\handlers\base.py", line 197, in _get_response
    response = wrapped_callback(request, *callback_args, **callback_kwargs)
  File "C:\Users\asati\AppData\Roaming\Python\Python313\site-packages\django\contrib\admin\options.py", line 718, in wrapper
    return self.admin_site.admin_view(view)(*args, **kwargs)
           ~~~~~~~~~~~~~~~~~~~~~~~~~~~~~~~~^^^^^^^^^^^^^^^^^
  File "C:\Users\asati\AppData\Roaming\Python\Python313\site-packages\django\utils\decorators.py", line 188, in _view_wrapper
    result = _process_exception(request, e)
  File "C:\Users\asati\AppData\Roaming\Python\Python313\site-packages\django\utils\decorators.py", line 186, in _view_wrapper
    response = view_func(request, *args, **kwargs)
  File "C:\Users\asati\AppData\Roaming\Python\Python313\site-packages\django\views\decorators\cache.py", line 80, in _view_wrapper
    response = view_func(request, *args, **kwargs)
  File "C:\Users\asati\AppData\Roaming\Python\Python313\site-packages\django\contrib\admin\sites.py", line 241, in inner
    return view(request, *args, **kwargs)
  File "C:\Users\asati\AppData\Roaming\Python\Python313\site-packages\django\contrib\admin\options.py", line 1961, in add_view
    return self.changeform_view(request, None, form_url, extra_context)
           ~~~~~~~~~~~~~~~~~~~~^^^^^^^^^^^^^^^^^^^^^^^^^^^^^^^^^^^^^^^^
  File "C:\Users\asati\AppData\Roaming\Python\Python313\site-packages\django\utils\decorators.py", line 48, in _wrapper
    return bound_method(*args, **kwargs)
  File "C:\Users\asati\AppData\Roaming\Python\Python313\site-packages\django\utils\decorators.py", line 188, in _view_wrapper
    result = _process_exception(request, e)
  File "C:\Users\asati\AppData\Roaming\Python\Python313\site-packages\django\utils\decorators.py", line 186, in _view_wrapper
    response = view_func(request, *args, **kwargs)
  File "C:\Users\asati\AppData\Roaming\Python\Python313\site-packages\django\contrib\admin\options.py", line 1820, in changeform_view
    return self._changeform_view(request, object_id, form_url, extra_context)
           ~~~~~~~~~~~~~~~~~~~~~^^^^^^^^^^^^^^^^^^^^^^^^^^^^^^^^^^^^^^^^^^^^^
  File "C:\Users\asati\AppData\Roaming\Python\Python313\site-packages\django\contrib\admin\options.py", line 1871, in _changeform_view
    self.save_model(request, new_object, form, not add)
    ~~~~~~~~~~~~~~~^^^^^^^^^^^^^^^^^^^^^^^^^^^^^^^^^^^^
  File "C:\Users\asati\AppData\Roaming\Python\Python313\site-packages\django\contrib\admin\options.py", line 1294, in save_model
    obj.save()
    ~~~~~~~~^^
  File "C:\Users\asati\OneDrive\Desktop\Live Projects\Type2Test\Type2Speed\typing_app\models.py", line 134, in save
    super().save(*args, **kwargs)
    ~~~~~~~~~~~~^^^^^^^^^^^^^^^^^
  File "C:\Users\asati\AppData\Roaming\Python\Python313\site-packages\django\db\models\base.py", line 892, in save
    self.save_base(
    ~~~~~~~~~~~~~~^
        using=using,
        ^^^^^^^^^^^^
    ...<2 lines>...
        update_fields=update_fields,
        ^^^^^^^^^^^^^^^^^^^^^^^^^^^^
    )
    ^
  File "C:\Users\asati\AppData\Roaming\Python\Python313\site-packages\django\db\models\base.py", line 998, in save_base
    updated = self._save_table(
        raw,
    ...<4 lines>...
        update_fields,
    )
  File "C:\Users\asati\AppData\Roaming\Python\Python313\site-packages\django\db\models\base.py", line 1161, in _save_table
    results = self._do_insert(
        cls._base_manager, using, fields, returning_fields, raw
    )
  File "C:\Users\asati\AppData\Roaming\Python\Python313\site-packages\django\db\models\base.py", line 1202, in _do_insert
    return manager._insert(
           ~~~~~~~~~~~~~~~^
        [self],
        ^^^^^^^
    ...<3 lines>...
        raw=raw,
        ^^^^^^^^
    )
    ^
  File "C:\Users\asati\AppData\Roaming\Python\Python313\site-packages\django\db\models\manager.py", line 87, in manager_method
    return getattr(self.get_queryset(), name)(*args, **kwargs)
           ~~~~~~~~~~~~~~~~~~~~~~~~~~~~~~~~~~^^^^^^^^^^^^^^^^^
  File "C:\Users\asati\AppData\Roaming\Python\Python313\site-packages\django\db\models\query.py", line 1847, in _insert
    return query.get_compiler(using=using).execute_sql(returning_fields)
           ~~~~~~~~~~~~~~~~~~~~~~~~~~~~~~~~~~~~~~~~~~~^^^^^^^^^^^^^^^^^^
  File "C:\Users\asati\AppData\Roaming\Python\Python313\site-packages\django\db\models\sql\compiler.py", line 1836, in execute_sql
    cursor.execute(sql, params)
    ~~~~~~~~~~~~~~^^^^^^^^^^^^^
  File "C:\Users\asati\AppData\Roaming\Python\Python313\site-packages\django\db\backends\utils.py", line 122, in execute
    return super().execute(sql, params)
           ~~~~~~~~~~~~~~~^^^^^^^^^^^^^
  File "C:\Users\asati\AppData\Roaming\Python\Python313\site-packages\django\db\backends\utils.py", line 79, in execute
    return self._execute_with_wrappers(
           ~~~~~~~~~~~~~~~~~~~~~~~~~~~^
        sql, params, many=False, executor=self._execute
        ^^^^^^^^^^^^^^^^^^^^^^^^^^^^^^^^^^^^^^^^^^^^^^^
    )
    ^
  File "C:\Users\asati\AppData\Roaming\Python\Python313\site-packages\django\db\backends\utils.py", line 92, in _execute_with_wrappers
    return executor(sql, params, many, context)
  File "C:\Users\asati\AppData\Roaming\Python\Python313\site-packages\django\db\backends\utils.py", line 100, in _execute
    with self.db.wrap_database_errors:
         ^^^^^^^^^^^^^^^^^^^^^^^^^^^^
  File "C:\Users\asati\AppData\Roaming\Python\Python313\site-packages\django\db\utils.py", line 91, in __exit__
    raise dj_exc_value.with_traceback(traceback) from exc_value
  File "C:\Users\asati\AppData\Roaming\Python\Python313\site-packages\django\db\backends\utils.py", line 105, in _execute
    return self.cursor.execute(sql, params)
           ~~~~~~~~~~~~~~~~~~~^^^^^^^^^^^^^
django.db.utils.DataError: value too long for type character varying(50)

"POST /admin/typing_app/blog/add/ HTTP/1.1" 500 232092
Internal Server Error: /test-result/PRACTISE/
Traceback (most recent call last):
  File "C:\Users\asati\AppData\Roaming\Python\Python313\site-packages\django\core\handlers\exception.py", line 55, in inner
    response = get_response(request)
  File "C:\Users\asati\AppData\Roaming\Python\Python313\site-packages\django\core\handlers\base.py", line 204, in _get_response
    self.check_response(response, callback)
    ~~~~~~~~~~~~~~~~~~~^^^^^^^^^^^^^^^^^^^^
  File "C:\Users\asati\AppData\Roaming\Python\Python313\site-packages\django\core\handlers\base.py", line 332, in check_response
    raise ValueError(
    ...<2 lines>...
    )
ValueError: The view typing_app.views.test_result_view didn't return an HttpResponse object. It returned None instead.
"POST /test-result/PRACTISE/ HTTP/1.1" 500 76909
Internal Server Error: /test-result/PRACTISE/
Traceback (most recent call last):
  File "C:\Users\asati\AppData\Roaming\Python\Python313\site-packages\django\core\handlers\exception.py", line 55, in inner
    response = get_response(request)
  File "C:\Users\asati\AppData\Roaming\Python\Python313\site-packages\django\core\handlers\base.py", line 197, in _get_response
    response = wrapped_callback(request, *callback_args, **callback_kwargs)
  File "C:\Users\asati\OneDrive\Desktop\Live Projects\Type2Test\Type2Speed\typing_app\views.py", line 414, in test_result_view
    passage = re.sub(r'\s+', ' ', passage)
                                  ^^^^^^^
UnboundLocalError: cannot access local variable 'passage' where it is not associated with a value
"POST /test-result/PRACTISE/ HTTP/1.1" 500 78420
Internal Server Error: /test-result/PRACTISE/
Traceback (most recent call last):
  File "C:\Users\asati\AppData\Roaming\Python\Python313\site-packages\django\core\handlers\exception.py", line 55, in inner
    response = get_response(request)
  File "C:\Users\asati\AppData\Roaming\Python\Python313\site-packages\django\core\handlers\base.py", line 197, in _get_response
    response = wrapped_callback(request, *callback_args, **callback_kwargs)
  File "C:\Users\asati\OneDrive\Desktop\Live Projects\Type2Test\Type2Speed\typing_app\views.py", line 414, in test_result_view
    passage = re.sub(r'\s+', ' ', passage)
                                  ^^^^^^^
UnboundLocalError: cannot access local variable 'passage' where it is not associated with a value
"POST /test-result/PRACTISE/ HTTP/1.1" 500 78374
Internal Server Error: /test-result/PRACTISE/
Traceback (most recent call last):
  File "C:\Users\asati\AppData\Roaming\Python\Python313\site-packages\django\core\handlers\exception.py", line 55, in inner
    response = get_response(request)
  File "C:\Users\asati\AppData\Roaming\Python\Python313\site-packages\django\core\handlers\base.py", line 197, in _get_response
    response = wrapped_callback(request, *callback_args, **callback_kwargs)
  File "C:\Users\asati\OneDrive\Desktop\Live Projects\Type2Test\Type2Speed\typing_app\views.py", line 416, in test_result_view
    passage = re.sub(r'\s+', ' ', passage)
                                  ^^^^^^^
UnboundLocalError: cannot access local variable 'passage' where it is not associated with a value
"POST /test-result/PRACTISE/ HTTP/1.1" 500 78357
Internal Server Error: /test-result/PRACTISE/
Traceback (most recent call last):
  File "C:\Users\asati\AppData\Roaming\Python\Python313\site-packages\django\core\handlers\exception.py", line 55, in inner
    response = get_response(request)
  File "C:\Users\asati\AppData\Roaming\Python\Python313\site-packages\django\core\handlers\base.py", line 197, in _get_response
    response = wrapped_callback(request, *callback_args, **callback_kwargs)
  File "C:\Users\asati\OneDrive\Desktop\Live Projects\Type2Test\Type2Speed\typing_app\views.py", line 416, in test_result_view
    passage = re.sub(r'\s+', ' ', passage)
                                  ^^^^^^^
UnboundLocalError: cannot access local variable 'passage' where it is not associated with a value
"POST /test-result/PRACTISE/ HTTP/1.1" 500 78329
Internal Server Error: /test-result/PRACTISE/
Traceback (most recent call last):
  File "C:\Users\asati\AppData\Roaming\Python\Python313\site-packages\django\core\handlers\exception.py", line 55, in inner
    response = get_response(request)
  File "C:\Users\asati\AppData\Roaming\Python\Python313\site-packages\django\core\handlers\base.py", line 197, in _get_response
    response = wrapped_callback(request, *callback_args, **callback_kwargs)
  File "C:\Users\asati\OneDrive\Desktop\Live Projects\Type2Test\Type2Speed\typing_app\views.py", line 416, in test_result_view
    passage = re.sub(r'\s+', ' ', passage)
                                  ^^^^^^^
UnboundLocalError: cannot access local variable 'passage' where it is not associated with a value
"POST /test-result/PRACTISE/ HTTP/1.1" 500 78329
Internal Server Error: /test-result/PRACTISE/
Traceback (most recent call last):
  File "C:\Users\asati\AppData\Roaming\Python\Python313\site-packages\django\core\handlers\exception.py", line 55, in inner
    response = get_response(request)
  File "C:\Users\asati\AppData\Roaming\Python\Python313\site-packages\django\core\handlers\base.py", line 197, in _get_response
    response = wrapped_callback(request, *callback_args, **callback_kwargs)
  File "C:\Users\asati\OneDrive\Desktop\Live Projects\Type2Test\Type2Speed\typing_app\views.py", line 416, in test_result_view
    passage = re.sub(r'\s+', ' ', passage)
                                  ^^^^^^^
UnboundLocalError: cannot access local variable 'passage' where it is not associated with a value
"POST /test-result/PRACTISE/ HTTP/1.1" 500 78355
Internal Server Error: /test-result/PRACTISE/
Traceback (most recent call last):
  File "C:\Users\asati\AppData\Roaming\Python\Python313\site-packages\django\core\handlers\exception.py", line 55, in inner
    response = get_response(request)
  File "C:\Users\asati\AppData\Roaming\Python\Python313\site-packages\django\core\handlers\base.py", line 197, in _get_response
    response = wrapped_callback(request, *callback_args, **callback_kwargs)
  File "C:\Users\asati\OneDrive\Desktop\Live Projects\Type2Test\Type2Speed\typing_app\views.py", line 416, in test_result_view
    passage = re.sub(r'\s+', ' ', passage)
                                  ^^^^^^^
UnboundLocalError: cannot access local variable 'passage' where it is not associated with a value
"POST /test-result/PRACTISE/?language=german HTTP/1.1" 500 78761
Internal Server Error: /test-result/PRACTISE/
Traceback (most recent call last):
  File "C:\Users\asati\AppData\Roaming\Python\Python313\site-packages\django\core\handlers\exception.py", line 55, in inner
    response = get_response(request)
  File "C:\Users\asati\AppData\Roaming\Python\Python313\site-packages\django\core\handlers\base.py", line 197, in _get_response
    response = wrapped_callback(request, *callback_args, **callback_kwargs)
  File "C:\Users\asati\OneDrive\Desktop\Live Projects\Type2Test\Type2Speed\typing_app\views.py", line 418, in test_result_view
    passage = re.sub(r'\s+', ' ', passage)
                                  ^^^^^^^
UnboundLocalError: cannot access local variable 'passage' where it is not associated with a value
"POST /test-result/PRACTISE/?language=german HTTP/1.1" 500 78925
Internal Server Error: /test-result/PRACTISE/
Traceback (most recent call last):
  File "C:\Users\asati\AppData\Roaming\Python\Python313\site-packages\django\core\handlers\exception.py", line 55, in inner
    response = get_response(request)
  File "C:\Users\asati\AppData\Roaming\Python\Python313\site-packages\django\core\handlers\base.py", line 204, in _get_response
    self.check_response(response, callback)
    ~~~~~~~~~~~~~~~~~~~^^^^^^^^^^^^^^^^^^^^
  File "C:\Users\asati\AppData\Roaming\Python\Python313\site-packages\django\core\handlers\base.py", line 332, in check_response
    raise ValueError(
    ...<2 lines>...
    )
ValueError: The view typing_app.views.test_result_view didn't return an HttpResponse object. It returned None instead.
"POST /test-result/PRACTISE/?language=german HTTP/1.1" 500 77277
Internal Server Error: /test-result/PRACTISE/
Traceback (most recent call last):
  File "C:\Users\asati\AppData\Roaming\Python\Python313\site-packages\django\core\handlers\exception.py", line 55, in inner
    response = get_response(request)
  File "C:\Users\asati\AppData\Roaming\Python\Python313\site-packages\django\core\handlers\base.py", line 204, in _get_response
    self.check_response(response, callback)
    ~~~~~~~~~~~~~~~~~~~^^^^^^^^^^^^^^^^^^^^
  File "C:\Users\asati\AppData\Roaming\Python\Python313\site-packages\django\core\handlers\base.py", line 332, in check_response
    raise ValueError(
    ...<2 lines>...
    )
ValueError: The view typing_app.views.test_result_view didn't return an HttpResponse object. It returned None instead.
"POST /test-result/PRACTISE/?language=german HTTP/1.1" 500 77277
Internal Server Error: /test-result/PRACTISE/
Traceback (most recent call last):
  File "C:\Users\asati\AppData\Roaming\Python\Python313\site-packages\django\core\handlers\exception.py", line 55, in inner
    response = get_response(request)
  File "C:\Users\asati\AppData\Roaming\Python\Python313\site-packages\django\core\handlers\base.py", line 204, in _get_response
    self.check_response(response, callback)
    ~~~~~~~~~~~~~~~~~~~^^^^^^^^^^^^^^^^^^^^
  File "C:\Users\asati\AppData\Roaming\Python\Python313\site-packages\django\core\handlers\base.py", line 332, in check_response
    raise ValueError(
    ...<2 lines>...
    )
ValueError: The view typing_app.views.test_result_view didn't return an HttpResponse object. It returned None instead.
"POST /test-result/PRACTISE/?language=german HTTP/1.1" 500 77277
Internal Server Error: /test-result/PRACTISE/
Traceback (most recent call last):
  File "C:\Users\asati\AppData\Roaming\Python\Python313\site-packages\django\core\handlers\exception.py", line 55, in inner
    response = get_response(request)
  File "C:\Users\asati\AppData\Roaming\Python\Python313\site-packages\django\core\handlers\base.py", line 204, in _get_response
    self.check_response(response, callback)
    ~~~~~~~~~~~~~~~~~~~^^^^^^^^^^^^^^^^^^^^
  File "C:\Users\asati\AppData\Roaming\Python\Python313\site-packages\django\core\handlers\base.py", line 332, in check_response
    raise ValueError(
    ...<2 lines>...
    )
ValueError: The view typing_app.views.test_result_view didn't return an HttpResponse object. It returned None instead.
"POST /test-result/PRACTISE/?language=german HTTP/1.1" 500 77277
Internal Server Error: /test-result/PRACTISE/
Traceback (most recent call last):
  File "C:\Users\asati\AppData\Roaming\Python\Python313\site-packages\django\core\handlers\exception.py", line 55, in inner
    response = get_response(request)
  File "C:\Users\asati\AppData\Roaming\Python\Python313\site-packages\django\core\handlers\base.py", line 204, in _get_response
    self.check_response(response, callback)
    ~~~~~~~~~~~~~~~~~~~^^^^^^^^^^^^^^^^^^^^
  File "C:\Users\asati\AppData\Roaming\Python\Python313\site-packages\django\core\handlers\base.py", line 332, in check_response
    raise ValueError(
    ...<2 lines>...
    )
ValueError: The view typing_app.views.test_result_view didn't return an HttpResponse object. It returned None instead.
"POST /test-result/PRACTISE/?language=german HTTP/1.1" 500 77275
Internal Server Error: /
Traceback (most recent call last):
  File "C:\Users\asati\AppData\Roaming\Python\Python313\site-packages\django\core\handlers\exception.py", line 55, in inner
    response = get_response(request)
  File "C:\Users\asati\AppData\Roaming\Python\Python313\site-packages\django\core\handlers\base.py", line 197, in _get_response
    response = wrapped_callback(request, *callback_args, **callback_kwargs)
  File "C:\Users\asati\OneDrive\Desktop\Live Projects\Type2Test\Type2Speed\typing_app\views.py", line 31, in home_view
    return render(request, "typing_app/home.html", {"exams": exams, "column_size": column_size,"ads": ads})
  File "C:\Users\asati\AppData\Roaming\Python\Python313\site-packages\django\shortcuts.py", line 25, in render
    content = loader.render_to_string(template_name, context, request, using=using)
  File "C:\Users\asati\AppData\Roaming\Python\Python313\site-packages\django\template\loader.py", line 62, in render_to_string
    return template.render(context, request)
           ~~~~~~~~~~~~~~~^^^^^^^^^^^^^^^^^^
  File "C:\Users\asati\AppData\Roaming\Python\Python313\site-packages\django\template\backends\django.py", line 107, in render
    return self.template.render(context)
           ~~~~~~~~~~~~~~~~~~~~^^^^^^^^^
  File "C:\Users\asati\AppData\Roaming\Python\Python313\site-packages\django\template\base.py", line 171, in render
    return self._render(context)
           ~~~~~~~~~~~~^^^^^^^^^
  File "C:\Users\asati\AppData\Roaming\Python\Python313\site-packages\django\template\base.py", line 163, in _render
    return self.nodelist.render(context)
           ~~~~~~~~~~~~~~~~~~~~^^^^^^^^^
  File "C:\Users\asati\AppData\Roaming\Python\Python313\site-packages\django\template\base.py", line 1008, in render
    return SafeString("".join([node.render_annotated(context) for node in self]))
                               ~~~~~~~~~~~~~~~~~~~~~^^^^^^^^^
  File "C:\Users\asati\AppData\Roaming\Python\Python313\site-packages\django\template\base.py", line 969, in render_annotated
    return self.render(context)
           ~~~~~~~~~~~^^^^^^^^^
  File "C:\Users\asati\AppData\Roaming\Python\Python313\site-packages\django\template\loader_tags.py", line 159, in render
    return compiled_parent._render(context)
           ~~~~~~~~~~~~~~~~~~~~~~~^^^^^^^^^
  File "C:\Users\asati\AppData\Roaming\Python\Python313\site-packages\django\template\base.py", line 163, in _render
    return self.nodelist.render(context)
           ~~~~~~~~~~~~~~~~~~~~^^^^^^^^^
  File "C:\Users\asati\AppData\Roaming\Python\Python313\site-packages\django\template\base.py", line 1008, in render
    return SafeString("".join([node.render_annotated(context) for node in self]))
                               ~~~~~~~~~~~~~~~~~~~~~^^^^^^^^^
  File "C:\Users\asati\AppData\Roaming\Python\Python313\site-packages\django\template\base.py", line 969, in render_annotated
    return self.render(context)
           ~~~~~~~~~~~^^^^^^^^^
  File "C:\Users\asati\AppData\Roaming\Python\Python313\site-packages\django\template\defaulttags.py", line 480, in render
    url = reverse(view_name, args=args, kwargs=kwargs, current_app=current_app)
  File "C:\Users\asati\AppData\Roaming\Python\Python313\site-packages\django\urls\base.py", line 88, in reverse
    return resolver._reverse_with_prefix(view, prefix, *args, **kwargs)
           ~~~~~~~~~~~~~~~~~~~~~~~~~~~~~^^^^^^^^^^^^^^^^^^^^^^^^^^^^^^^
  File "C:\Users\asati\AppData\Roaming\Python\Python313\site-packages\django\urls\resolvers.py", line 831, in _reverse_with_prefix
    raise NoReverseMatch(msg)
django.urls.exceptions.NoReverseMatch: Reverse for 'learn' not found. 'learn' is not a valid view function or pattern name.
"GET / HTTP/1.1" 500 149953
Internal Server Error: /
Traceback (most recent call last):
  File "C:\Users\asati\AppData\Roaming\Python\Python313\site-packages\django\core\handlers\exception.py", line 55, in inner
    response = get_response(request)
  File "C:\Users\asati\AppData\Roaming\Python\Python313\site-packages\django\core\handlers\base.py", line 197, in _get_response
    response = wrapped_callback(request, *callback_args, **callback_kwargs)
  File "C:\Users\asati\OneDrive\Desktop\Live Projects\Type2Test\Type2Speed\typing_app\views.py", line 31, in home_view
    return render(request, "typing_app/home.html", {"exams": exams, "column_size": column_size,"ads": ads})
  File "C:\Users\asati\AppData\Roaming\Python\Python313\site-packages\django\shortcuts.py", line 25, in render
    content = loader.render_to_string(template_name, context, request, using=using)
  File "C:\Users\asati\AppData\Roaming\Python\Python313\site-packages\django\template\loader.py", line 62, in render_to_string
    return template.render(context, request)
           ~~~~~~~~~~~~~~~^^^^^^^^^^^^^^^^^^
  File "C:\Users\asati\AppData\Roaming\Python\Python313\site-packages\django\template\backends\django.py", line 107, in render
    return self.template.render(context)
           ~~~~~~~~~~~~~~~~~~~~^^^^^^^^^
  File "C:\Users\asati\AppData\Roaming\Python\Python313\site-packages\django\template\base.py", line 171, in render
    return self._render(context)
           ~~~~~~~~~~~~^^^^^^^^^
  File "C:\Users\asati\AppData\Roaming\Python\Python313\site-packages\django\template\base.py", line 163, in _render
    return self.nodelist.render(context)
           ~~~~~~~~~~~~~~~~~~~~^^^^^^^^^
  File "C:\Users\asati\AppData\Roaming\Python\Python313\site-packages\django\template\base.py", line 1008, in render
    return SafeString("".join([node.render_annotated(context) for node in self]))
                               ~~~~~~~~~~~~~~~~~~~~~^^^^^^^^^
  File "C:\Users\asati\AppData\Roaming\Python\Python313\site-packages\django\template\base.py", line 969, in render_annotated
    return self.render(context)
           ~~~~~~~~~~~^^^^^^^^^
  File "C:\Users\asati\AppData\Roaming\Python\Python313\site-packages\django\template\loader_tags.py", line 159, in render
    return compiled_parent._render(context)
           ~~~~~~~~~~~~~~~~~~~~~~~^^^^^^^^^
  File "C:\Users\asati\AppData\Roaming\Python\Python313\site-packages\django\template\base.py", line 163, in _render
    return self.nodelist.render(context)
           ~~~~~~~~~~~~~~~~~~~~^^^^^^^^^
  File "C:\Users\asati\AppData\Roaming\Python\Python313\site-packages\django\template\base.py", line 1008, in render
    return SafeString("".join([node.render_annotated(context) for node in self]))
                               ~~~~~~~~~~~~~~~~~~~~~^^^^^^^^^
  File "C:\Users\asati\AppData\Roaming\Python\Python313\site-packages\django\template\base.py", line 969, in render_annotated
    return self.render(context)
           ~~~~~~~~~~~^^^^^^^^^
  File "C:\Users\asati\AppData\Roaming\Python\Python313\site-packages\django\template\defaulttags.py", line 480, in render
    url = reverse(view_name, args=args, kwargs=kwargs, current_app=current_app)
  File "C:\Users\asati\AppData\Roaming\Python\Python313\site-packages\django\urls\base.py", line 88, in reverse
    return resolver._reverse_with_prefix(view, prefix, *args, **kwargs)
           ~~~~~~~~~~~~~~~~~~~~~~~~~~~~~^^^^^^^^^^^^^^^^^^^^^^^^^^^^^^^
  File "C:\Users\asati\AppData\Roaming\Python\Python313\site-packages\django\urls\resolvers.py", line 831, in _reverse_with_prefix
    raise NoReverseMatch(msg)
django.urls.exceptions.NoReverseMatch: Reverse for 'learn' not found. 'learn' is not a valid view function or pattern name.
"GET / HTTP/1.1" 500 149775
"GET /practise-instructions/PRACTISE/ HTTP/1.1" 500 149102
Internal Server Error: /tests/
Traceback (most recent call last):
  File "C:\Users\asati\AppData\Roaming\Python\Python313\site-packages\django\core\handlers\exception.py", line 55, in inner
    response = get_response(request)
  File "C:\Users\asati\AppData\Roaming\Python\Python313\site-packages\django\core\handlers\base.py", line 197, in _get_response
    response = wrapped_callback(request, *callback_args, **callback_kwargs)
  File "C:\Users\asati\OneDrive\Desktop\Live Projects\Type2Test\Type2Speed\typing_app\views.py", line 44, in tests_view
    return render(request, "typing_app/tests.html", {"exams": exams, "column_size": column_size})
  File "C:\Users\asati\AppData\Roaming\Python\Python313\site-packages\django\shortcuts.py", line 25, in render
    content = loader.render_to_string(template_name, context, request, using=using)
  File "C:\Users\asati\AppData\Roaming\Python\Python313\site-packages\django\template\loader.py", line 62, in render_to_string
    return template.render(context, request)
           ~~~~~~~~~~~~~~~^^^^^^^^^^^^^^^^^^
  File "C:\Users\asati\AppData\Roaming\Python\Python313\site-packages\django\template\backends\django.py", line 107, in render
    return self.template.render(context)
           ~~~~~~~~~~~~~~~~~~~~^^^^^^^^^
  File "C:\Users\asati\AppData\Roaming\Python\Python313\site-packages\django\template\base.py", line 171, in render
    return self._render(context)
           ~~~~~~~~~~~~^^^^^^^^^
  File "C:\Users\asati\AppData\Roaming\Python\Python313\site-packages\django\template\base.py", line 163, in _render
    return self.nodelist.render(context)
           ~~~~~~~~~~~~~~~~~~~~^^^^^^^^^
  File "C:\Users\asati\AppData\Roaming\Python\Python313\site-packages\django\template\base.py", line 1008, in render
    return SafeString("".join([node.render_annotated(context) for node in self]))
                               ~~~~~~~~~~~~~~~~~~~~~^^^^^^^^^
  File "C:\Users\asati\AppData\Roaming\Python\Python313\site-packages\django\template\base.py", line 969, in render_annotated
    return self.render(context)
           ~~~~~~~~~~~^^^^^^^^^
  File "C:\Users\asati\AppData\Roaming\Python\Python313\site-packages\django\template\loader_tags.py", line 159, in render
    return compiled_parent._render(context)
           ~~~~~~~~~~~~~~~~~~~~~~~^^^^^^^^^
  File "C:\Users\asati\AppData\Roaming\Python\Python313\site-packages\django\template\base.py", line 163, in _render
    return self.nodelist.render(context)
           ~~~~~~~~~~~~~~~~~~~~^^^^^^^^^
  File "C:\Users\asati\AppData\Roaming\Python\Python313\site-packages\django\template\base.py", line 1008, in render
    return SafeString("".join([node.render_annotated(context) for node in self]))
                               ~~~~~~~~~~~~~~~~~~~~~^^^^^^^^^
  File "C:\Users\asati\AppData\Roaming\Python\Python313\site-packages\django\template\base.py", line 969, in render_annotated
    return self.render(context)
           ~~~~~~~~~~~^^^^^^^^^
  File "C:\Users\asati\AppData\Roaming\Python\Python313\site-packages\django\template\defaulttags.py", line 480, in render
    url = reverse(view_name, args=args, kwargs=kwargs, current_app=current_app)
  File "C:\Users\asati\AppData\Roaming\Python\Python313\site-packages\django\urls\base.py", line 88, in reverse
    return resolver._reverse_with_prefix(view, prefix, *args, **kwargs)
           ~~~~~~~~~~~~~~~~~~~~~~~~~~~~~^^^^^^^^^^^^^^^^^^^^^^^^^^^^^^^
  File "C:\Users\asati\AppData\Roaming\Python\Python313\site-packages\django\urls\resolvers.py", line 831, in _reverse_with_prefix
    raise NoReverseMatch(msg)
django.urls.exceptions.NoReverseMatch: Reverse for 'language' not found. 'language' is not a valid view function or pattern name.
"GET /tests/ HTTP/1.1" 500 147964
Internal Server Error: /tests/
Traceback (most recent call last):
  File "C:\Users\asati\AppData\Roaming\Python\Python313\site-packages\django\core\handlers\exception.py", line 55, in inner
    response = get_response(request)
  File "C:\Users\asati\AppData\Roaming\Python\Python313\site-packages\django\core\handlers\base.py", line 197, in _get_response
    response = wrapped_callback(request, *callback_args, **callback_kwargs)
  File "C:\Users\asati\OneDrive\Desktop\Live Projects\Type2Test\Type2Speed\typing_app\views.py", line 44, in tests_view
    return render(request, "typing_app/tests.html", {"exams": exams, "column_size": column_size})
  File "C:\Users\asati\AppData\Roaming\Python\Python313\site-packages\django\shortcuts.py", line 25, in render
    content = loader.render_to_string(template_name, context, request, using=using)
  File "C:\Users\asati\AppData\Roaming\Python\Python313\site-packages\django\template\loader.py", line 62, in render_to_string
    return template.render(context, request)
           ~~~~~~~~~~~~~~~^^^^^^^^^^^^^^^^^^
  File "C:\Users\asati\AppData\Roaming\Python\Python313\site-packages\django\template\backends\django.py", line 107, in render
    return self.template.render(context)
           ~~~~~~~~~~~~~~~~~~~~^^^^^^^^^
  File "C:\Users\asati\AppData\Roaming\Python\Python313\site-packages\django\template\base.py", line 171, in render
    return self._render(context)
           ~~~~~~~~~~~~^^^^^^^^^
  File "C:\Users\asati\AppData\Roaming\Python\Python313\site-packages\django\template\base.py", line 163, in _render
    return self.nodelist.render(context)
           ~~~~~~~~~~~~~~~~~~~~^^^^^^^^^
  File "C:\Users\asati\AppData\Roaming\Python\Python313\site-packages\django\template\base.py", line 1008, in render
    return SafeString("".join([node.render_annotated(context) for node in self]))
                               ~~~~~~~~~~~~~~~~~~~~~^^^^^^^^^
  File "C:\Users\asati\AppData\Roaming\Python\Python313\site-packages\django\template\base.py", line 969, in render_annotated
    return self.render(context)
           ~~~~~~~~~~~^^^^^^^^^
  File "C:\Users\asati\AppData\Roaming\Python\Python313\site-packages\django\template\loader_tags.py", line 159, in render
    return compiled_parent._render(context)
           ~~~~~~~~~~~~~~~~~~~~~~~^^^^^^^^^
  File "C:\Users\asati\AppData\Roaming\Python\Python313\site-packages\django\template\base.py", line 163, in _render
    return self.nodelist.render(context)
           ~~~~~~~~~~~~~~~~~~~~^^^^^^^^^
  File "C:\Users\asati\AppData\Roaming\Python\Python313\site-packages\django\template\base.py", line 1008, in render
    return SafeString("".join([node.render_annotated(context) for node in self]))
                               ~~~~~~~~~~~~~~~~~~~~~^^^^^^^^^
  File "C:\Users\asati\AppData\Roaming\Python\Python313\site-packages\django\template\base.py", line 969, in render_annotated
    return self.render(context)
           ~~~~~~~~~~~^^^^^^^^^
  File "C:\Users\asati\AppData\Roaming\Python\Python313\site-packages\django\template\defaulttags.py", line 480, in render
    url = reverse(view_name, args=args, kwargs=kwargs, current_app=current_app)
  File "C:\Users\asati\AppData\Roaming\Python\Python313\site-packages\django\urls\base.py", line 88, in reverse
    return resolver._reverse_with_prefix(view, prefix, *args, **kwargs)
           ~~~~~~~~~~~~~~~~~~~~~~~~~~~~~^^^^^^^^^^^^^^^^^^^^^^^^^^^^^^^
  File "C:\Users\asati\AppData\Roaming\Python\Python313\site-packages\django\urls\resolvers.py", line 831, in _reverse_with_prefix
    raise NoReverseMatch(msg)
django.urls.exceptions.NoReverseMatch: Reverse for 'language' not found. 'language' is not a valid view function or pattern name.
"GET /tests/ HTTP/1.1" 500 147964
Internal Server Error: /tests/
Traceback (most recent call last):
  File "C:\Users\asati\AppData\Roaming\Python\Python313\site-packages\django\core\handlers\exception.py", line 55, in inner
    response = get_response(request)
  File "C:\Users\asati\AppData\Roaming\Python\Python313\site-packages\django\core\handlers\base.py", line 197, in _get_response
    response = wrapped_callback(request, *callback_args, **callback_kwargs)
  File "C:\Users\asati\OneDrive\Desktop\Live Projects\Type2Test\Type2Speed\typing_app\views.py", line 44, in tests_view
    return render(request, "typing_app/tests.html", {"exams": exams, "column_size": column_size})
  File "C:\Users\asati\AppData\Roaming\Python\Python313\site-packages\django\shortcuts.py", line 25, in render
    content = loader.render_to_string(template_name, context, request, using=using)
  File "C:\Users\asati\AppData\Roaming\Python\Python313\site-packages\django\template\loader.py", line 62, in render_to_string
    return template.render(context, request)
           ~~~~~~~~~~~~~~~^^^^^^^^^^^^^^^^^^
  File "C:\Users\asati\AppData\Roaming\Python\Python313\site-packages\django\template\backends\django.py", line 107, in render
    return self.template.render(context)
           ~~~~~~~~~~~~~~~~~~~~^^^^^^^^^
  File "C:\Users\asati\AppData\Roaming\Python\Python313\site-packages\django\template\base.py", line 171, in render
    return self._render(context)
           ~~~~~~~~~~~~^^^^^^^^^
  File "C:\Users\asati\AppData\Roaming\Python\Python313\site-packages\django\template\base.py", line 163, in _render
    return self.nodelist.render(context)
           ~~~~~~~~~~~~~~~~~~~~^^^^^^^^^
  File "C:\Users\asati\AppData\Roaming\Python\Python313\site-packages\django\template\base.py", line 1008, in render
    return SafeString("".join([node.render_annotated(context) for node in self]))
                               ~~~~~~~~~~~~~~~~~~~~~^^^^^^^^^
  File "C:\Users\asati\AppData\Roaming\Python\Python313\site-packages\django\template\base.py", line 969, in render_annotated
    return self.render(context)
           ~~~~~~~~~~~^^^^^^^^^
  File "C:\Users\asati\AppData\Roaming\Python\Python313\site-packages\django\template\loader_tags.py", line 159, in render
    return compiled_parent._render(context)
           ~~~~~~~~~~~~~~~~~~~~~~~^^^^^^^^^
  File "C:\Users\asati\AppData\Roaming\Python\Python313\site-packages\django\template\base.py", line 163, in _render
    return self.nodelist.render(context)
           ~~~~~~~~~~~~~~~~~~~~^^^^^^^^^
  File "C:\Users\asati\AppData\Roaming\Python\Python313\site-packages\django\template\base.py", line 1008, in render
    return SafeString("".join([node.render_annotated(context) for node in self]))
                               ~~~~~~~~~~~~~~~~~~~~~^^^^^^^^^
  File "C:\Users\asati\AppData\Roaming\Python\Python313\site-packages\django\template\base.py", line 969, in render_annotated
    return self.render(context)
           ~~~~~~~~~~~^^^^^^^^^
  File "C:\Users\asati\AppData\Roaming\Python\Python313\site-packages\django\template\defaulttags.py", line 480, in render
    url = reverse(view_name, args=args, kwargs=kwargs, current_app=current_app)
  File "C:\Users\asati\AppData\Roaming\Python\Python313\site-packages\django\urls\base.py", line 88, in reverse
    return resolver._reverse_with_prefix(view, prefix, *args, **kwargs)
           ~~~~~~~~~~~~~~~~~~~~~~~~~~~~~^^^^^^^^^^^^^^^^^^^^^^^^^^^^^^^
  File "C:\Users\asati\AppData\Roaming\Python\Python313\site-packages\django\urls\resolvers.py", line 831, in _reverse_with_prefix
    raise NoReverseMatch(msg)
django.urls.exceptions.NoReverseMatch: Reverse for 'language' not found. 'language' is not a valid view function or pattern name.
"GET /tests/ HTTP/1.1" 500 148101
Internal Server Error: /tests/
Traceback (most recent call last):
  File "C:\Users\asati\AppData\Roaming\Python\Python313\site-packages\django\core\handlers\exception.py", line 55, in inner
    response = get_response(request)
  File "C:\Users\asati\AppData\Roaming\Python\Python313\site-packages\django\core\handlers\base.py", line 197, in _get_response
    response = wrapped_callback(request, *callback_args, **callback_kwargs)
  File "C:\Users\asati\OneDrive\Desktop\Live Projects\Type2Test\Type2Speed\typing_app\views.py", line 44, in tests_view
    return render(request, "typing_app/tests.html", {"exams": exams, "column_size": column_size})
  File "C:\Users\asati\AppData\Roaming\Python\Python313\site-packages\django\shortcuts.py", line 25, in render
    content = loader.render_to_string(template_name, context, request, using=using)
  File "C:\Users\asati\AppData\Roaming\Python\Python313\site-packages\django\template\loader.py", line 62, in render_to_string
    return template.render(context, request)
           ~~~~~~~~~~~~~~~^^^^^^^^^^^^^^^^^^
  File "C:\Users\asati\AppData\Roaming\Python\Python313\site-packages\django\template\backends\django.py", line 107, in render
    return self.template.render(context)
           ~~~~~~~~~~~~~~~~~~~~^^^^^^^^^
  File "C:\Users\asati\AppData\Roaming\Python\Python313\site-packages\django\template\base.py", line 171, in render
    return self._render(context)
           ~~~~~~~~~~~~^^^^^^^^^
  File "C:\Users\asati\AppData\Roaming\Python\Python313\site-packages\django\template\base.py", line 163, in _render
    return self.nodelist.render(context)
           ~~~~~~~~~~~~~~~~~~~~^^^^^^^^^
  File "C:\Users\asati\AppData\Roaming\Python\Python313\site-packages\django\template\base.py", line 1008, in render
    return SafeString("".join([node.render_annotated(context) for node in self]))
                               ~~~~~~~~~~~~~~~~~~~~~^^^^^^^^^
  File "C:\Users\asati\AppData\Roaming\Python\Python313\site-packages\django\template\base.py", line 969, in render_annotated
    return self.render(context)
           ~~~~~~~~~~~^^^^^^^^^
  File "C:\Users\asati\AppData\Roaming\Python\Python313\site-packages\django\template\loader_tags.py", line 159, in render
    return compiled_parent._render(context)
           ~~~~~~~~~~~~~~~~~~~~~~~^^^^^^^^^
  File "C:\Users\asati\AppData\Roaming\Python\Python313\site-packages\django\template\base.py", line 163, in _render
    return self.nodelist.render(context)
           ~~~~~~~~~~~~~~~~~~~~^^^^^^^^^
  File "C:\Users\asati\AppData\Roaming\Python\Python313\site-packages\django\template\base.py", line 1008, in render
    return SafeString("".join([node.render_annotated(context) for node in self]))
                               ~~~~~~~~~~~~~~~~~~~~~^^^^^^^^^
  File "C:\Users\asati\AppData\Roaming\Python\Python313\site-packages\django\template\base.py", line 969, in render_annotated
    return self.render(context)
           ~~~~~~~~~~~^^^^^^^^^
  File "C:\Users\asati\AppData\Roaming\Python\Python313\site-packages\django\template\defaulttags.py", line 480, in render
    url = reverse(view_name, args=args, kwargs=kwargs, current_app=current_app)
  File "C:\Users\asati\AppData\Roaming\Python\Python313\site-packages\django\urls\base.py", line 88, in reverse
    return resolver._reverse_with_prefix(view, prefix, *args, **kwargs)
           ~~~~~~~~~~~~~~~~~~~~~~~~~~~~~^^^^^^^^^^^^^^^^^^^^^^^^^^^^^^^
  File "C:\Users\asati\AppData\Roaming\Python\Python313\site-packages\django\urls\resolvers.py", line 831, in _reverse_with_prefix
    raise NoReverseMatch(msg)
django.urls.exceptions.NoReverseMatch: Reverse for 'language' not found. 'language' is not a valid view function or pattern name.
"GET /tests/ HTTP/1.1" 500 148101
Internal Server Error: /tests/
Traceback (most recent call last):
  File "C:\Users\asati\AppData\Roaming\Python\Python313\site-packages\django\core\handlers\exception.py", line 55, in inner
    response = get_response(request)
  File "C:\Users\asati\AppData\Roaming\Python\Python313\site-packages\django\core\handlers\base.py", line 197, in _get_response
    response = wrapped_callback(request, *callback_args, **callback_kwargs)
  File "C:\Users\asati\OneDrive\Desktop\Live Projects\Type2Test\Type2Speed\typing_app\views.py", line 44, in tests_view
    return render(request, "typing_app/tests.html", {"exams": exams, "column_size": column_size})
  File "C:\Users\asati\AppData\Roaming\Python\Python313\site-packages\django\shortcuts.py", line 25, in render
    content = loader.render_to_string(template_name, context, request, using=using)
  File "C:\Users\asati\AppData\Roaming\Python\Python313\site-packages\django\template\loader.py", line 62, in render_to_string
    return template.render(context, request)
           ~~~~~~~~~~~~~~~^^^^^^^^^^^^^^^^^^
  File "C:\Users\asati\AppData\Roaming\Python\Python313\site-packages\django\template\backends\django.py", line 107, in render
    return self.template.render(context)
           ~~~~~~~~~~~~~~~~~~~~^^^^^^^^^
  File "C:\Users\asati\AppData\Roaming\Python\Python313\site-packages\django\template\base.py", line 171, in render
    return self._render(context)
           ~~~~~~~~~~~~^^^^^^^^^
  File "C:\Users\asati\AppData\Roaming\Python\Python313\site-packages\django\template\base.py", line 163, in _render
    return self.nodelist.render(context)
           ~~~~~~~~~~~~~~~~~~~~^^^^^^^^^
  File "C:\Users\asati\AppData\Roaming\Python\Python313\site-packages\django\template\base.py", line 1008, in render
    return SafeString("".join([node.render_annotated(context) for node in self]))
                               ~~~~~~~~~~~~~~~~~~~~~^^^^^^^^^
  File "C:\Users\asati\AppData\Roaming\Python\Python313\site-packages\django\template\base.py", line 969, in render_annotated
    return self.render(context)
           ~~~~~~~~~~~^^^^^^^^^
  File "C:\Users\asati\AppData\Roaming\Python\Python313\site-packages\django\template\loader_tags.py", line 159, in render
    return compiled_parent._render(context)
           ~~~~~~~~~~~~~~~~~~~~~~~^^^^^^^^^
  File "C:\Users\asati\AppData\Roaming\Python\Python313\site-packages\django\template\base.py", line 163, in _render
    return self.nodelist.render(context)
           ~~~~~~~~~~~~~~~~~~~~^^^^^^^^^
  File "C:\Users\asati\AppData\Roaming\Python\Python313\site-packages\django\template\base.py", line 1008, in render
    return SafeString("".join([node.render_annotated(context) for node in self]))
                               ~~~~~~~~~~~~~~~~~~~~~^^^^^^^^^
  File "C:\Users\asati\AppData\Roaming\Python\Python313\site-packages\django\template\base.py", line 969, in render_annotated
    return self.render(context)
           ~~~~~~~~~~~^^^^^^^^^
  File "C:\Users\asati\AppData\Roaming\Python\Python313\site-packages\django\template\defaulttags.py", line 480, in render
    url = reverse(view_name, args=args, kwargs=kwargs, current_app=current_app)
  File "C:\Users\asati\AppData\Roaming\Python\Python313\site-packages\django\urls\base.py", line 88, in reverse
    return resolver._reverse_with_prefix(view, prefix, *args, **kwargs)
           ~~~~~~~~~~~~~~~~~~~~~~~~~~~~~^^^^^^^^^^^^^^^^^^^^^^^^^^^^^^^
  File "C:\Users\asati\AppData\Roaming\Python\Python313\site-packages\django\urls\resolvers.py", line 831, in _reverse_with_prefix
    raise NoReverseMatch(msg)
django.urls.exceptions.NoReverseMatch: Reverse for 'language' not found. 'language' is not a valid view function or pattern name.
"GET /tests/ HTTP/1.1" 500 148101
Internal Server Error: /tests/
Traceback (most recent call last):
  File "C:\Users\asati\AppData\Roaming\Python\Python313\site-packages\django\core\handlers\exception.py", line 55, in inner
    response = get_response(request)
  File "C:\Users\asati\AppData\Roaming\Python\Python313\site-packages\django\core\handlers\base.py", line 197, in _get_response
    response = wrapped_callback(request, *callback_args, **callback_kwargs)
  File "C:\Users\asati\OneDrive\Desktop\Live Projects\Type2Test\Type2Speed\typing_app\views.py", line 44, in tests_view
    return render(request, "typing_app/tests.html", {"exams": exams, "column_size": column_size})
  File "C:\Users\asati\AppData\Roaming\Python\Python313\site-packages\django\shortcuts.py", line 25, in render
    content = loader.render_to_string(template_name, context, request, using=using)
  File "C:\Users\asati\AppData\Roaming\Python\Python313\site-packages\django\template\loader.py", line 62, in render_to_string
    return template.render(context, request)
           ~~~~~~~~~~~~~~~^^^^^^^^^^^^^^^^^^
  File "C:\Users\asati\AppData\Roaming\Python\Python313\site-packages\django\template\backends\django.py", line 107, in render
    return self.template.render(context)
           ~~~~~~~~~~~~~~~~~~~~^^^^^^^^^
  File "C:\Users\asati\AppData\Roaming\Python\Python313\site-packages\django\template\base.py", line 171, in render
    return self._render(context)
           ~~~~~~~~~~~~^^^^^^^^^
  File "C:\Users\asati\AppData\Roaming\Python\Python313\site-packages\django\template\base.py", line 163, in _render
    return self.nodelist.render(context)
           ~~~~~~~~~~~~~~~~~~~~^^^^^^^^^
  File "C:\Users\asati\AppData\Roaming\Python\Python313\site-packages\django\template\base.py", line 1008, in render
    return SafeString("".join([node.render_annotated(context) for node in self]))
                               ~~~~~~~~~~~~~~~~~~~~~^^^^^^^^^
  File "C:\Users\asati\AppData\Roaming\Python\Python313\site-packages\django\template\base.py", line 969, in render_annotated
    return self.render(context)
           ~~~~~~~~~~~^^^^^^^^^
  File "C:\Users\asati\AppData\Roaming\Python\Python313\site-packages\django\template\loader_tags.py", line 159, in render
    return compiled_parent._render(context)
           ~~~~~~~~~~~~~~~~~~~~~~~^^^^^^^^^
  File "C:\Users\asati\AppData\Roaming\Python\Python313\site-packages\django\template\base.py", line 163, in _render
    return self.nodelist.render(context)
           ~~~~~~~~~~~~~~~~~~~~^^^^^^^^^
  File "C:\Users\asati\AppData\Roaming\Python\Python313\site-packages\django\template\base.py", line 1008, in render
    return SafeString("".join([node.render_annotated(context) for node in self]))
                               ~~~~~~~~~~~~~~~~~~~~~^^^^^^^^^
  File "C:\Users\asati\AppData\Roaming\Python\Python313\site-packages\django\template\base.py", line 969, in render_annotated
    return self.render(context)
           ~~~~~~~~~~~^^^^^^^^^
  File "C:\Users\asati\AppData\Roaming\Python\Python313\site-packages\django\template\defaulttags.py", line 480, in render
    url = reverse(view_name, args=args, kwargs=kwargs, current_app=current_app)
  File "C:\Users\asati\AppData\Roaming\Python\Python313\site-packages\django\urls\base.py", line 88, in reverse
    return resolver._reverse_with_prefix(view, prefix, *args, **kwargs)
           ~~~~~~~~~~~~~~~~~~~~~~~~~~~~~^^^^^^^^^^^^^^^^^^^^^^^^^^^^^^^
  File "C:\Users\asati\AppData\Roaming\Python\Python313\site-packages\django\urls\resolvers.py", line 831, in _reverse_with_prefix
    raise NoReverseMatch(msg)
django.urls.exceptions.NoReverseMatch: Reverse for 'language' not found. 'language' is not a valid view function or pattern name.
Internal Server Error: /tests/
Traceback (most recent call last):
  File "C:\Users\asati\AppData\Roaming\Python\Python313\site-packages\django\core\handlers\exception.py", line 55, in inner
    response = get_response(request)
  File "C:\Users\asati\AppData\Roaming\Python\Python313\site-packages\django\core\handlers\base.py", line 197, in _get_response
    response = wrapped_callback(request, *callback_args, **callback_kwargs)
  File "C:\Users\asati\OneDrive\Desktop\Live Projects\Type2Test\Type2Speed\typing_app\views.py", line 44, in tests_view
    return render(request, "typing_app/tests.html", {"exams": exams, "column_size": column_size})
  File "C:\Users\asati\AppData\Roaming\Python\Python313\site-packages\django\shortcuts.py", line 25, in render
    content = loader.render_to_string(template_name, context, request, using=using)
  File "C:\Users\asati\AppData\Roaming\Python\Python313\site-packages\django\template\loader.py", line 62, in render_to_string
    return template.render(context, request)
           ~~~~~~~~~~~~~~~^^^^^^^^^^^^^^^^^^
  File "C:\Users\asati\AppData\Roaming\Python\Python313\site-packages\django\template\backends\django.py", line 107, in render
    return self.template.render(context)
           ~~~~~~~~~~~~~~~~~~~~^^^^^^^^^
  File "C:\Users\asati\AppData\Roaming\Python\Python313\site-packages\django\template\base.py", line 171, in render
    return self._render(context)
           ~~~~~~~~~~~~^^^^^^^^^
  File "C:\Users\asati\AppData\Roaming\Python\Python313\site-packages\django\template\base.py", line 163, in _render
    return self.nodelist.render(context)
           ~~~~~~~~~~~~~~~~~~~~^^^^^^^^^
  File "C:\Users\asati\AppData\Roaming\Python\Python313\site-packages\django\template\base.py", line 1008, in render
    return SafeString("".join([node.render_annotated(context) for node in self]))
                               ~~~~~~~~~~~~~~~~~~~~~^^^^^^^^^
  File "C:\Users\asati\AppData\Roaming\Python\Python313\site-packages\django\template\base.py", line 969, in render_annotated
    return self.render(context)
           ~~~~~~~~~~~^^^^^^^^^
  File "C:\Users\asati\AppData\Roaming\Python\Python313\site-packages\django\template\loader_tags.py", line 159, in render
    return compiled_parent._render(context)
           ~~~~~~~~~~~~~~~~~~~~~~~^^^^^^^^^
  File "C:\Users\asati\AppData\Roaming\Python\Python313\site-packages\django\template\base.py", line 163, in _render
    return self.nodelist.render(context)
           ~~~~~~~~~~~~~~~~~~~~^^^^^^^^^
  File "C:\Users\asati\AppData\Roaming\Python\Python313\site-packages\django\template\base.py", line 1008, in render
    return SafeString("".join([node.render_annotated(context) for node in self]))
                               ~~~~~~~~~~~~~~~~~~~~~^^^^^^^^^
  File "C:\Users\asati\AppData\Roaming\Python\Python313\site-packages\django\template\base.py", line 969, in render_annotated
    return self.render(context)
           ~~~~~~~~~~~^^^^^^^^^
  File "C:\Users\asati\AppData\Roaming\Python\Python313\site-packages\django\template\defaulttags.py", line 480, in render
    url = reverse(view_name, args=args, kwargs=kwargs, current_app=current_app)
  File "C:\Users\asati\AppData\Roaming\Python\Python313\site-packages\django\urls\base.py", line 88, in reverse
    return resolver._reverse_with_prefix(view, prefix, *args, **kwargs)
           ~~~~~~~~~~~~~~~~~~~~~~~~~~~~~^^^^^^^^^^^^^^^^^^^^^^^^^^^^^^^
  File "C:\Users\asati\AppData\Roaming\Python\Python313\site-packages\django\urls\resolvers.py", line 831, in _reverse_with_prefix
    raise NoReverseMatch(msg)
django.urls.exceptions.NoReverseMatch: Reverse for 'language' not found. 'language' is not a valid view function or pattern name.
"GET /tests/ HTTP/1.1" 500 148101
"GET /typing-test/ARO/english/2/ HTTP/1.1" 500 249970
Internal Server Error: /languages/
Traceback (most recent call last):
  File "C:\Users\asati\AppData\Roaming\Python\Python313\site-packages\django\core\handlers\exception.py", line 55, in inner
    response = get_response(request)
  File "C:\Users\asati\AppData\Roaming\Python\Python313\site-packages\django\core\handlers\base.py", line 197, in _get_response
    response = wrapped_callback(request, *callback_args, **callback_kwargs)
  File "C:\Users\asati\OneDrive\Desktop\Live Projects\Type2Test\Type2Speed\typing_app\views.py", line 573, in languages
    return render(request, 'navbar/languages.html')
  File "C:\Users\asati\AppData\Roaming\Python\Python313\site-packages\django\shortcuts.py", line 25, in render
    content = loader.render_to_string(template_name, context, request, using=using)
  File "C:\Users\asati\AppData\Roaming\Python\Python313\site-packages\django\template\loader.py", line 62, in render_to_string
    return template.render(context, request)
           ~~~~~~~~~~~~~~~^^^^^^^^^^^^^^^^^^
  File "C:\Users\asati\AppData\Roaming\Python\Python313\site-packages\django\template\backends\django.py", line 107, in render
    return self.template.render(context)
           ~~~~~~~~~~~~~~~~~~~~^^^^^^^^^
  File "C:\Users\asati\AppData\Roaming\Python\Python313\site-packages\django\template\base.py", line 171, in render
    return self._render(context)
           ~~~~~~~~~~~~^^^^^^^^^
  File "C:\Users\asati\AppData\Roaming\Python\Python313\site-packages\django\template\base.py", line 163, in _render
    return self.nodelist.render(context)
           ~~~~~~~~~~~~~~~~~~~~^^^^^^^^^
  File "C:\Users\asati\AppData\Roaming\Python\Python313\site-packages\django\template\base.py", line 1008, in render
    return SafeString("".join([node.render_annotated(context) for node in self]))
                               ~~~~~~~~~~~~~~~~~~~~~^^^^^^^^^
  File "C:\Users\asati\AppData\Roaming\Python\Python313\site-packages\django\template\base.py", line 969, in render_annotated
    return self.render(context)
           ~~~~~~~~~~~^^^^^^^^^
  File "C:\Users\asati\AppData\Roaming\Python\Python313\site-packages\django\template\loader_tags.py", line 159, in render
    return compiled_parent._render(context)
           ~~~~~~~~~~~~~~~~~~~~~~~^^^^^^^^^
  File "C:\Users\asati\AppData\Roaming\Python\Python313\site-packages\django\template\base.py", line 163, in _render
    return self.nodelist.render(context)
           ~~~~~~~~~~~~~~~~~~~~^^^^^^^^^
  File "C:\Users\asati\AppData\Roaming\Python\Python313\site-packages\django\template\base.py", line 1008, in render
    return SafeString("".join([node.render_annotated(context) for node in self]))
                               ~~~~~~~~~~~~~~~~~~~~~^^^^^^^^^
  File "C:\Users\asati\AppData\Roaming\Python\Python313\site-packages\django\template\base.py", line 969, in render_annotated
    return self.render(context)
           ~~~~~~~~~~~^^^^^^^^^
  File "C:\Users\asati\AppData\Roaming\Python\Python313\site-packages\django\template\loader_tags.py", line 65, in render
    result = block.nodelist.render(context)
  File "C:\Users\asati\AppData\Roaming\Python\Python313\site-packages\django\template\base.py", line 1008, in render
    return SafeString("".join([node.render_annotated(context) for node in self]))
                               ~~~~~~~~~~~~~~~~~~~~~^^^^^^^^^
  File "C:\Users\asati\AppData\Roaming\Python\Python313\site-packages\django\template\base.py", line 969, in render_annotated
    return self.render(context)
           ~~~~~~~~~~~^^^^^^^^^
  File "C:\Users\asati\AppData\Roaming\Python\Python313\site-packages\django\template\defaulttags.py", line 480, in render
    url = reverse(view_name, args=args, kwargs=kwargs, current_app=current_app)
  File "C:\Users\asati\AppData\Roaming\Python\Python313\site-packages\django\urls\base.py", line 88, in reverse
    return resolver._reverse_with_prefix(view, prefix, *args, **kwargs)
           ~~~~~~~~~~~~~~~~~~~~~~~~~~~~~^^^^^^^^^^^^^^^^^^^^^^^^^^^^^^^
  File "C:\Users\asati\AppData\Roaming\Python\Python313\site-packages\django\urls\resolvers.py", line 831, in _reverse_with_prefix
    raise NoReverseMatch(msg)
django.urls.exceptions.NoReverseMatch: Reverse for 'proceed_to_test' not found. 'proceed_to_test' is not a valid view function or pattern name.
"GET /languages/ HTTP/1.1" 500 160597
Internal Server Error: /languages/
Traceback (most recent call last):
  File "C:\Users\asati\AppData\Roaming\Python\Python313\site-packages\django\core\handlers\exception.py", line 55, in inner
    response = get_response(request)
  File "C:\Users\asati\AppData\Roaming\Python\Python313\site-packages\django\core\handlers\base.py", line 197, in _get_response
    response = wrapped_callback(request, *callback_args, **callback_kwargs)
  File "C:\Users\asati\OneDrive\Desktop\Live Projects\Type2Test\Type2Speed\typing_app\views.py", line 576, in languages
    return render(request, 'navbar/languages.html')
  File "C:\Users\asati\AppData\Roaming\Python\Python313\site-packages\django\shortcuts.py", line 25, in render
    content = loader.render_to_string(template_name, context, request, using=using)
  File "C:\Users\asati\AppData\Roaming\Python\Python313\site-packages\django\template\loader.py", line 62, in render_to_string
    return template.render(context, request)
           ~~~~~~~~~~~~~~~^^^^^^^^^^^^^^^^^^
  File "C:\Users\asati\AppData\Roaming\Python\Python313\site-packages\django\template\backends\django.py", line 107, in render
    return self.template.render(context)
           ~~~~~~~~~~~~~~~~~~~~^^^^^^^^^
  File "C:\Users\asati\AppData\Roaming\Python\Python313\site-packages\django\template\base.py", line 171, in render
    return self._render(context)
           ~~~~~~~~~~~~^^^^^^^^^
  File "C:\Users\asati\AppData\Roaming\Python\Python313\site-packages\django\template\base.py", line 163, in _render
    return self.nodelist.render(context)
           ~~~~~~~~~~~~~~~~~~~~^^^^^^^^^
  File "C:\Users\asati\AppData\Roaming\Python\Python313\site-packages\django\template\base.py", line 1008, in render
    return SafeString("".join([node.render_annotated(context) for node in self]))
                               ~~~~~~~~~~~~~~~~~~~~~^^^^^^^^^
  File "C:\Users\asati\AppData\Roaming\Python\Python313\site-packages\django\template\base.py", line 969, in render_annotated
    return self.render(context)
           ~~~~~~~~~~~^^^^^^^^^
  File "C:\Users\asati\AppData\Roaming\Python\Python313\site-packages\django\template\loader_tags.py", line 159, in render
    return compiled_parent._render(context)
           ~~~~~~~~~~~~~~~~~~~~~~~^^^^^^^^^
  File "C:\Users\asati\AppData\Roaming\Python\Python313\site-packages\django\template\base.py", line 163, in _render
    return self.nodelist.render(context)
           ~~~~~~~~~~~~~~~~~~~~^^^^^^^^^
  File "C:\Users\asati\AppData\Roaming\Python\Python313\site-packages\django\template\base.py", line 1008, in render
    return SafeString("".join([node.render_annotated(context) for node in self]))
                               ~~~~~~~~~~~~~~~~~~~~~^^^^^^^^^
  File "C:\Users\asati\AppData\Roaming\Python\Python313\site-packages\django\template\base.py", line 969, in render_annotated
    return self.render(context)
           ~~~~~~~~~~~^^^^^^^^^
  File "C:\Users\asati\AppData\Roaming\Python\Python313\site-packages\django\template\loader_tags.py", line 65, in render
    result = block.nodelist.render(context)
  File "C:\Users\asati\AppData\Roaming\Python\Python313\site-packages\django\template\base.py", line 1008, in render
    return SafeString("".join([node.render_annotated(context) for node in self]))
                               ~~~~~~~~~~~~~~~~~~~~~^^^^^^^^^
  File "C:\Users\asati\AppData\Roaming\Python\Python313\site-packages\django\template\base.py", line 969, in render_annotated
    return self.render(context)
           ~~~~~~~~~~~^^^^^^^^^
  File "C:\Users\asati\AppData\Roaming\Python\Python313\site-packages\django\template\defaulttags.py", line 480, in render
    url = reverse(view_name, args=args, kwargs=kwargs, current_app=current_app)
  File "C:\Users\asati\AppData\Roaming\Python\Python313\site-packages\django\urls\base.py", line 88, in reverse
    return resolver._reverse_with_prefix(view, prefix, *args, **kwargs)
           ~~~~~~~~~~~~~~~~~~~~~~~~~~~~~^^^^^^^^^^^^^^^^^^^^^^^^^^^^^^^
  File "C:\Users\asati\AppData\Roaming\Python\Python313\site-packages\django\urls\resolvers.py", line 831, in _reverse_with_prefix
    raise NoReverseMatch(msg)
django.urls.exceptions.NoReverseMatch: Reverse for 'passages-languages' with keyword arguments '{'exam_type': 'PRACTISE', 'language': ''}' not found. 1 pattern(s) tried: ['passages/(?P<exam_type>[^/]+)/(?P<language>[^/]+)/\\Z']
"GET /languages/ HTTP/1.1" 500 166309
"GET /languages/ HTTP/1.1" 500 90840
"GET /languages/ HTTP/1.1" 500 90760
"GET /languages/ HTTP/1.1" 500 170333
"GET /languages/ HTTP/1.1" 500 170333
"GET /languages/ HTTP/1.1" 500 170186
"GET /languages/ HTTP/1.1" 500 170472
"GET /languages/ HTTP/1.1" 500 170335
"GET /languages/ HTTP/1.1" 500 170223
"GET /languages/ HTTP/1.1" 500 170225
"GET /languages/ HTTP/1.1" 500 166138
Internal Server Error: /passages/PRACTISE/English/15/
Traceback (most recent call last):
  File "C:\Users\asati\AppData\Roaming\Python\Python313\site-packages\django\core\handlers\exception.py", line 55, in inner
    response = get_response(request)
  File "C:\Users\asati\AppData\Roaming\Python\Python313\site-packages\django\core\handlers\base.py", line 197, in _get_response
    response = wrapped_callback(request, *callback_args, **callback_kwargs)
TypeError: passages_languages_view() got an unexpected keyword argument 'exam_type'
"GET /passages/PRACTISE/English/15/?csrfmiddlewaretoken=I3xPFIk0kzQpL4YDY6i1tuBnrxOQ3aVamnMKExD72EsHN3wMjnV1D5W7xeDebZ0j HTTP/1.1" 500 71381
Internal Server Error: /passages/PRACTISE/English/15/
Traceback (most recent call last):
  File "C:\Users\asati\AppData\Roaming\Python\Python313\site-packages\django\core\handlers\exception.py", line 55, in inner
    response = get_response(request)
  File "C:\Users\asati\AppData\Roaming\Python\Python313\site-packages\django\core\handlers\base.py", line 197, in _get_response
    response = wrapped_callback(request, *callback_args, **callback_kwargs)
TypeError: passages_languages_view() got an unexpected keyword argument 'exam_type'
"GET /passages/PRACTISE/English/15/?csrfmiddlewaretoken=I3xPFIk0kzQpL4YDY6i1tuBnrxOQ3aVamnMKExD72EsHN3wMjnV1D5W7xeDebZ0j HTTP/1.1" 500 71381
Internal Server Error: /passages/PRACTISE/English/15/
Traceback (most recent call last):
  File "C:\Users\asati\AppData\Roaming\Python\Python313\site-packages\django\core\handlers\exception.py", line 55, in inner
    response = get_response(request)
  File "C:\Users\asati\AppData\Roaming\Python\Python313\site-packages\django\core\handlers\base.py", line 197, in _get_response
    response = wrapped_callback(request, *callback_args, **callback_kwargs)
TypeError: passages_languages_view() got an unexpected keyword argument 'exam_type'
"GET /passages/PRACTISE/English/15/?csrfmiddlewaretoken=I3xPFIk0kzQpL4YDY6i1tuBnrxOQ3aVamnMKExD72EsHN3wMjnV1D5W7xeDebZ0j HTTP/1.1" 500 71381
Internal Server Error: /passages/PRACTISE/English/15/
Traceback (most recent call last):
  File "C:\Users\asati\AppData\Roaming\Python\Python313\site-packages\django\core\handlers\exception.py", line 55, in inner
    response = get_response(request)
  File "C:\Users\asati\AppData\Roaming\Python\Python313\site-packages\django\core\handlers\base.py", line 197, in _get_response
    response = wrapped_callback(request, *callback_args, **callback_kwargs)
TypeError: passages_languages_view() got an unexpected keyword argument 'exam_type'
"GET /passages/PRACTISE/English/15/?csrfmiddlewaretoken=I3xPFIk0kzQpL4YDY6i1tuBnrxOQ3aVamnMKExD72EsHN3wMjnV1D5W7xeDebZ0j HTTP/1.1" 500 71518
Internal Server Error: /passages/PRACTISE/English/15/
Traceback (most recent call last):
  File "C:\Users\asati\AppData\Roaming\Python\Python313\site-packages\django\core\handlers\exception.py", line 55, in inner
    response = get_response(request)
  File "C:\Users\asati\AppData\Roaming\Python\Python313\site-packages\django\core\handlers\base.py", line 197, in _get_response
    response = wrapped_callback(request, *callback_args, **callback_kwargs)
TypeError: passages_languages_view() got an unexpected keyword argument 'exam_type'
"GET /passages/PRACTISE/English/15/?csrfmiddlewaretoken=I3xPFIk0kzQpL4YDY6i1tuBnrxOQ3aVamnMKExD72EsHN3wMjnV1D5W7xeDebZ0j HTTP/1.1" 500 71381
Internal Server Error: /passages/PRACTISE/English/15/
Traceback (most recent call last):
  File "C:\Users\asati\AppData\Roaming\Python\Python313\site-packages\django\core\handlers\exception.py", line 55, in inner
    response = get_response(request)
  File "C:\Users\asati\AppData\Roaming\Python\Python313\site-packages\django\core\handlers\base.py", line 197, in _get_response
    response = wrapped_callback(request, *callback_args, **callback_kwargs)
TypeError: typing_test_view() got an unexpected keyword argument 'duration'
"GET /passages/PRACTISE/English/15/?csrfmiddlewaretoken=ByqM2nLGuNYKmmWj21SfFrzpBHy6Eh4CfSFH1c4NcSA2olusnivfP2U9HonuM69L HTTP/1.1" 500 71328
Internal Server Error: /passages/PRACTISE/English/15/
Traceback (most recent call last):
  File "C:\Users\asati\AppData\Roaming\Python\Python313\site-packages\django\core\handlers\exception.py", line 55, in inner
    response = get_response(request)
  File "C:\Users\asati\AppData\Roaming\Python\Python313\site-packages\django\core\handlers\base.py", line 197, in _get_response
    response = wrapped_callback(request, *callback_args, **callback_kwargs)
TypeError: typing_test_view() got an unexpected keyword argument 'duration'
"GET /passages/PRACTISE/English/15/?csrfmiddlewaretoken=ByqM2nLGuNYKmmWj21SfFrzpBHy6Eh4CfSFH1c4NcSA2olusnivfP2U9HonuM69L HTTP/1.1" 500 71465
"GET /languages/ HTTP/1.1" 500 171196
"GET /languages/ HTTP/1.1" 500 171312
"GET /languages/ HTTP/1.1" 500 171312
"GET /languages/ HTTP/1.1" 500 171175
"GET /languages/ HTTP/1.1" 500 171175
"GET /languages/ HTTP/1.1" 500 171175
"GET /languages/ HTTP/1.1" 500 167605
"GET /languages/ HTTP/1.1" 500 167468
