Internal Server Error: /
Traceback (most recent call last):
  File "C:\Users\asati\AppData\Roaming\Python\Python313\site-packages\django\core\handlers\exception.py", line 55, in inner
    response = get_response(request)
  File "C:\Users\asati\AppData\Roaming\Python\Python313\site-packages\django\core\handlers\base.py", line 197, in _get_response
    response = wrapped_callback(request, *callback_args, **callback_kwargs)
  File "C:\Users\asati\OneDrive\Desktop\Live Projects\Type2Test\Type2Speed\typing_app\views.py", line 45, in home_view
    column_size = 12 // min(exam_count, 4)  # Dynamically calculate the column size
                  ~~~^^~~~~~~~~~~~~~~~~~~~
ZeroDivisionError: integer division or modulo by zero
"GET / HTTP/1.1" 500 74260
Internal Server Error: /
Traceback (most recent call last):
  File "C:\Users\asati\AppData\Roaming\Python\Python313\site-packages\django\core\handlers\exception.py", line 55, in inner
    response = get_response(request)
  File "C:\Users\asati\AppData\Roaming\Python\Python313\site-packages\django\core\handlers\base.py", line 197, in _get_response
    response = wrapped_callback(request, *callback_args, **callback_kwargs)
  File "C:\Users\asati\OneDrive\Desktop\Live Projects\Type2Test\Type2Speed\typing_app\views.py", line 45, in home_view
    column_size = 12 // min(exam_count, 4)  # Dynamically calculate the column size
                  ~~~^^~~~~~~~~~~~~~~~~~~~
ZeroDivisionError: integer division or modulo by zero
"GET / HTTP/1.1" 500 74111
Internal Server Error: /test-result/CPCT/
Traceback (most recent call last):
  File "C:\Users\asati\AppData\Roaming\Python\Python313\site-packages\django\core\handlers\exception.py", line 55, in inner
    response = get_response(request)
  File "C:\Users\asati\AppData\Roaming\Python\Python313\site-packages\django\core\handlers\base.py", line 197, in _get_response
    response = wrapped_callback(request, *callback_args, **callback_kwargs)
  File "C:\Users\asati\OneDrive\Desktop\Live Projects\Type2Test\Type2Speed\typing_app\views.py", line 402, in test_result_view
    passage = re.sub(r'\s+', ' ', exam_content.passage.strip())
                                  ^^^^^^^^^^^^^^^^^^^^
AttributeError: 'ExamContent' object has no attribute 'passage'
"POST /test-result/CPCT/ HTTP/1.1" 500 78494
"GET /typing-test/PRACTISE/english/127/ HTTP/1.1" 500 77277
"GET /typing-test/PRACTISE/english/127/ HTTP/1.1" 500 77277
"GET /typing-test/PRACTISE/english/127/ HTTP/1.1" 500 77277
Internal Server Error: /test-result/CPCT/
Traceback (most recent call last):
  File "C:\Users\asati\AppData\Roaming\Python\Python313\site-packages\django\core\handlers\exception.py", line 55, in inner
    response = get_response(request)
  File "C:\Users\asati\AppData\Roaming\Python\Python313\site-packages\django\core\handlers\base.py", line 197, in _get_response
    response = wrapped_callback(request, *callback_args, **callback_kwargs)
  File "C:\Users\asati\OneDrive\Desktop\Live Projects\Type2Test\Type2Speed\typing_app\views.py", line 408, in test_result_view
    passage = re.sub(r'\s+', ' ', exam_content.passage_english.strip())  # Use passage_english
                                  ^^^^^^^^^^^^^^^^^^^^^^^^^^^^^^^^^^
AttributeError: 'NoneType' object has no attribute 'strip'
"POST /test-result/CPCT/ HTTP/1.1" 500 78534
Internal Server Error: /ads.txt/
Traceback (most recent call last):
  File "C:\Users\asati\AppData\Roaming\Python\Python313\site-packages\django\core\handlers\exception.py", line 55, in inner
    response = get_response(request)
  File "C:\Users\asati\AppData\Roaming\Python\Python313\site-packages\django\core\handlers\base.py", line 197, in _get_response
    response = wrapped_callback(request, *callback_args, **callback_kwargs)
TypeError: ads_get() missing 1 required positional argument: 'request'
"GET /ads.txt/ HTTP/1.1" 500 69922
Internal Server Error: /sitemap.xml
Traceback (most recent call last):
  File "C:\Users\asati\AppData\Roaming\Python\Python313\site-packages\django\core\handlers\exception.py", line 55, in inner
    response = get_response(request)
  File "C:\Users\asati\AppData\Roaming\Python\Python313\site-packages\django\core\handlers\base.py", line 197, in _get_response
    response = wrapped_callback(request, *callback_args, **callback_kwargs)
  File "C:\Users\asati\AppData\Roaming\Python\Python313\site-packages\django\contrib\sitemaps\views.py", line 23, in inner
    response = func(request, *args, **kwargs)
  File "C:\Users\asati\AppData\Roaming\Python\Python313\site-packages\django\contrib\sitemaps\views.py", line 117, in sitemap
    urls.extend(site.get_urls(page=page, site=req_site, protocol=req_protocol))
                ~~~~~~~~~~~~~^^^^^^^^^^^^^^^^^^^^^^^^^^^^^^^^^^^^^^^^^^^^^^^^^
  File "C:\Users\asati\AppData\Roaming\Python\Python313\site-packages\django\contrib\sitemaps\__init__.py", line 104, in get_urls
    return self._urls(page, protocol, domain)
           ~~~~~~~~~~^^^^^^^^^^^^^^^^^^^^^^^^
  File "C:\Users\asati\AppData\Roaming\Python\Python313\site-packages\django\contrib\sitemaps\__init__.py", line 124, in _urls
    loc = f"{protocol}://{domain}{self._location(item)}"
                                  ~~~~~~~~~~~~~~^^^^^^
  File "C:\Users\asati\AppData\Roaming\Python\Python313\site-packages\django\contrib\sitemaps\__init__.py", line 69, in _location
    return self._get("location", item)
           ~~~~~~~~~^^^^^^^^^^^^^^^^^^
  File "C:\Users\asati\AppData\Roaming\Python\Python313\site-packages\django\contrib\sitemaps\__init__.py", line 39, in _get
    return attr(item)
  File "C:\Users\asati\OneDrive\Desktop\Live Projects\Type2Test\Type2Speed\typing_app\sitemaps.py", line 7, in location
    return reverse(item)
  File "C:\Users\asati\AppData\Roaming\Python\Python313\site-packages\django\urls\base.py", line 88, in reverse
    return resolver._reverse_with_prefix(view, prefix, *args, **kwargs)
           ~~~~~~~~~~~~~~~~~~~~~~~~~~~~~^^^^^^^^^^^^^^^^^^^^^^^^^^^^^^^
  File "C:\Users\asati\AppData\Roaming\Python\Python313\site-packages\django\urls\resolvers.py", line 831, in _reverse_with_prefix
    raise NoReverseMatch(msg)
django.urls.exceptions.NoReverseMatch: Reverse for 'about' not found. 'about' is not a valid view function or pattern name.
"GET /sitemap.xml HTTP/1.1" 500 110757
Internal Server Error: /sitemap.xml
Traceback (most recent call last):
  File "C:\Users\asati\AppData\Roaming\Python\Python313\site-packages\django\core\handlers\exception.py", line 55, in inner
    response = get_response(request)
  File "C:\Users\asati\AppData\Roaming\Python\Python313\site-packages\django\core\handlers\base.py", line 197, in _get_response
    response = wrapped_callback(request, *callback_args, **callback_kwargs)
  File "C:\Users\asati\AppData\Roaming\Python\Python313\site-packages\django\contrib\sitemaps\views.py", line 23, in inner
    response = func(request, *args, **kwargs)
  File "C:\Users\asati\AppData\Roaming\Python\Python313\site-packages\django\contrib\sitemaps\views.py", line 117, in sitemap
    urls.extend(site.get_urls(page=page, site=req_site, protocol=req_protocol))
                ~~~~~~~~~~~~~^^^^^^^^^^^^^^^^^^^^^^^^^^^^^^^^^^^^^^^^^^^^^^^^^
  File "C:\Users\asati\AppData\Roaming\Python\Python313\site-packages\django\contrib\sitemaps\__init__.py", line 104, in get_urls
    return self._urls(page, protocol, domain)
           ~~~~~~~~~~^^^^^^^^^^^^^^^^^^^^^^^^
  File "C:\Users\asati\AppData\Roaming\Python\Python313\site-packages\django\contrib\sitemaps\__init__.py", line 124, in _urls
    loc = f"{protocol}://{domain}{self._location(item)}"
                                  ~~~~~~~~~~~~~~^^^^^^
  File "C:\Users\asati\AppData\Roaming\Python\Python313\site-packages\django\contrib\sitemaps\__init__.py", line 69, in _location
    return self._get("location", item)
           ~~~~~~~~~^^^^^^^^^^^^^^^^^^
  File "C:\Users\asati\AppData\Roaming\Python\Python313\site-packages\django\contrib\sitemaps\__init__.py", line 39, in _get
    return attr(item)
  File "C:\Users\asati\OneDrive\Desktop\Live Projects\Type2Test\Type2Speed\typing_app\sitemaps.py", line 10, in location
    return reverse(item)
  File "C:\Users\asati\AppData\Roaming\Python\Python313\site-packages\django\urls\base.py", line 88, in reverse
    return resolver._reverse_with_prefix(view, prefix, *args, **kwargs)
           ~~~~~~~~~~~~~~~~~~~~~~~~~~~~~^^^^^^^^^^^^^^^^^^^^^^^^^^^^^^^
  File "C:\Users\asati\AppData\Roaming\Python\Python313\site-packages\django\urls\resolvers.py", line 831, in _reverse_with_prefix
    raise NoReverseMatch(msg)
django.urls.exceptions.NoReverseMatch: Reverse for 'instructions' with no arguments not found. 1 pattern(s) tried: ['instructions/(?P<exam_type>[^/]+)/(?P<passage_id>[0-9]+)/\\Z']
"GET /sitemap.xml HTTP/1.1" 500 115432
Internal Server Error: /sitemap.xml
Traceback (most recent call last):
  File "C:\Users\asati\AppData\Roaming\Python\Python313\site-packages\django\core\handlers\exception.py", line 55, in inner
    response = get_response(request)
  File "C:\Users\asati\AppData\Roaming\Python\Python313\site-packages\django\core\handlers\base.py", line 197, in _get_response
    response = wrapped_callback(request, *callback_args, **callback_kwargs)
  File "C:\Users\asati\AppData\Roaming\Python\Python313\site-packages\django\contrib\sitemaps\views.py", line 23, in inner
    response = func(request, *args, **kwargs)
  File "C:\Users\asati\AppData\Roaming\Python\Python313\site-packages\django\contrib\sitemaps\views.py", line 117, in sitemap
    urls.extend(site.get_urls(page=page, site=req_site, protocol=req_protocol))
                ~~~~~~~~~~~~~^^^^^^^^^^^^^^^^^^^^^^^^^^^^^^^^^^^^^^^^^^^^^^^^^
  File "C:\Users\asati\AppData\Roaming\Python\Python313\site-packages\django\contrib\sitemaps\__init__.py", line 104, in get_urls
    return self._urls(page, protocol, domain)
           ~~~~~~~~~~^^^^^^^^^^^^^^^^^^^^^^^^
  File "C:\Users\asati\AppData\Roaming\Python\Python313\site-packages\django\contrib\sitemaps\__init__.py", line 124, in _urls
    loc = f"{protocol}://{domain}{self._location(item)}"
                                  ~~~~~~~~~~~~~~^^^^^^
  File "C:\Users\asati\AppData\Roaming\Python\Python313\site-packages\django\contrib\sitemaps\__init__.py", line 69, in _location
    return self._get("location", item)
           ~~~~~~~~~^^^^^^^^^^^^^^^^^^
  File "C:\Users\asati\AppData\Roaming\Python\Python313\site-packages\django\contrib\sitemaps\__init__.py", line 39, in _get
    return attr(item)
  File "C:\Users\asati\OneDrive\Desktop\Live Projects\Type2Test\Type2Speed\typing_app\sitemaps.py", line 10, in location
    return reverse(item)
  File "C:\Users\asati\AppData\Roaming\Python\Python313\site-packages\django\urls\base.py", line 88, in reverse
    return resolver._reverse_with_prefix(view, prefix, *args, **kwargs)
           ~~~~~~~~~~~~~~~~~~~~~~~~~~~~~^^^^^^^^^^^^^^^^^^^^^^^^^^^^^^^
  File "C:\Users\asati\AppData\Roaming\Python\Python313\site-packages\django\urls\resolvers.py", line 831, in _reverse_with_prefix
    raise NoReverseMatch(msg)
django.urls.exceptions.NoReverseMatch: Reverse for 'games' not found. 'games' is not a valid view function or pattern name.
"GET /sitemap.xml HTTP/1.1" 500 114575
Internal Server Error: /sitemap.xml
Traceback (most recent call last):
  File "C:\Users\asati\AppData\Roaming\Python\Python313\site-packages\django\core\handlers\exception.py", line 55, in inner
    response = get_response(request)
  File "C:\Users\asati\AppData\Roaming\Python\Python313\site-packages\django\core\handlers\base.py", line 220, in _get_response
    response = response.render()
  File "C:\Users\asati\AppData\Roaming\Python\Python313\site-packages\django\template\response.py", line 114, in render
    self.content = self.rendered_content
                   ^^^^^^^^^^^^^^^^^^^^^
  File "C:\Users\asati\AppData\Roaming\Python\Python313\site-packages\django\template\response.py", line 90, in rendered_content
    template = self.resolve_template(self.template_name)
  File "C:\Users\asati\AppData\Roaming\Python\Python313\site-packages\django\template\response.py", line 74, in resolve_template
    return get_template(template, using=self.using)
  File "C:\Users\asati\AppData\Roaming\Python\Python313\site-packages\django\template\loader.py", line 19, in get_template
    raise TemplateDoesNotExist(template_name, chain=chain)
django.template.exceptions.TemplateDoesNotExist: sitemap.xml
"GET /sitemap.xml HTTP/1.1" 500 87573
Internal Server Error: /sitemap.xml
Traceback (most recent call last):
  File "C:\Users\asati\AppData\Roaming\Python\Python313\site-packages\django\core\handlers\exception.py", line 55, in inner
    response = get_response(request)
  File "C:\Users\asati\AppData\Roaming\Python\Python313\site-packages\django\core\handlers\base.py", line 220, in _get_response
    response = response.render()
  File "C:\Users\asati\AppData\Roaming\Python\Python313\site-packages\django\template\response.py", line 114, in render
    self.content = self.rendered_content
                   ^^^^^^^^^^^^^^^^^^^^^
  File "C:\Users\asati\AppData\Roaming\Python\Python313\site-packages\django\template\response.py", line 90, in rendered_content
    template = self.resolve_template(self.template_name)
  File "C:\Users\asati\AppData\Roaming\Python\Python313\site-packages\django\template\response.py", line 74, in resolve_template
    return get_template(template, using=self.using)
  File "C:\Users\asati\AppData\Roaming\Python\Python313\site-packages\django\template\loader.py", line 19, in get_template
    raise TemplateDoesNotExist(template_name, chain=chain)
django.template.exceptions.TemplateDoesNotExist: sitemap.xml
"GET /sitemap.xml HTTP/1.1" 500 87573
Internal Server Error: /sitemap.xml
Traceback (most recent call last):
  File "C:\Users\asati\AppData\Roaming\Python\Python313\site-packages\django\core\handlers\exception.py", line 55, in inner
    response = get_response(request)
  File "C:\Users\asati\AppData\Roaming\Python\Python313\site-packages\django\core\handlers\base.py", line 220, in _get_response
    response = response.render()
  File "C:\Users\asati\AppData\Roaming\Python\Python313\site-packages\django\template\response.py", line 114, in render
    self.content = self.rendered_content
                   ^^^^^^^^^^^^^^^^^^^^^
  File "C:\Users\asati\AppData\Roaming\Python\Python313\site-packages\django\template\response.py", line 90, in rendered_content
    template = self.resolve_template(self.template_name)
  File "C:\Users\asati\AppData\Roaming\Python\Python313\site-packages\django\template\response.py", line 74, in resolve_template
    return get_template(template, using=self.using)
  File "C:\Users\asati\AppData\Roaming\Python\Python313\site-packages\django\template\loader.py", line 19, in get_template
    raise TemplateDoesNotExist(template_name, chain=chain)
django.template.exceptions.TemplateDoesNotExist: sitemap.xml
"GET /sitemap.xml HTTP/1.1" 500 87764
Internal Server Error: /sitemap.xml
Traceback (most recent call last):
  File "C:\Users\asati\AppData\Roaming\Python\Python313\site-packages\django\core\handlers\exception.py", line 55, in inner
    response = get_response(request)
  File "C:\Users\asati\AppData\Roaming\Python\Python313\site-packages\django\core\handlers\base.py", line 220, in _get_response
    response = response.render()
  File "C:\Users\asati\AppData\Roaming\Python\Python313\site-packages\django\template\response.py", line 114, in render
    self.content = self.rendered_content
                   ^^^^^^^^^^^^^^^^^^^^^
  File "C:\Users\asati\AppData\Roaming\Python\Python313\site-packages\django\template\response.py", line 90, in rendered_content
    template = self.resolve_template(self.template_name)
  File "C:\Users\asati\AppData\Roaming\Python\Python313\site-packages\django\template\response.py", line 74, in resolve_template
    return get_template(template, using=self.using)
  File "C:\Users\asati\AppData\Roaming\Python\Python313\site-packages\django\template\loader.py", line 19, in get_template
    raise TemplateDoesNotExist(template_name, chain=chain)
django.template.exceptions.TemplateDoesNotExist: sitemap.xml
"GET /sitemap.xml HTTP/1.1" 500 87764
Internal Server Error: /sitemap.xml
Traceback (most recent call last):
  File "C:\Users\asati\AppData\Roaming\Python\Python313\site-packages\django\core\handlers\exception.py", line 55, in inner
    response = get_response(request)
  File "C:\Users\asati\AppData\Roaming\Python\Python313\site-packages\django\core\handlers\base.py", line 220, in _get_response
    response = response.render()
  File "C:\Users\asati\AppData\Roaming\Python\Python313\site-packages\django\template\response.py", line 114, in render
    self.content = self.rendered_content
                   ^^^^^^^^^^^^^^^^^^^^^
  File "C:\Users\asati\AppData\Roaming\Python\Python313\site-packages\django\template\response.py", line 90, in rendered_content
    template = self.resolve_template(self.template_name)
  File "C:\Users\asati\AppData\Roaming\Python\Python313\site-packages\django\template\response.py", line 74, in resolve_template
    return get_template(template, using=self.using)
  File "C:\Users\asati\AppData\Roaming\Python\Python313\site-packages\django\template\loader.py", line 19, in get_template
    raise TemplateDoesNotExist(template_name, chain=chain)
django.template.exceptions.TemplateDoesNotExist: sitemap.xml
"GET /sitemap.xml HTTP/1.1" 500 87764
Internal Server Error: /sitemap.xml
Traceback (most recent call last):
  File "C:\Users\asati\AppData\Roaming\Python\Python313\site-packages\django\core\handlers\exception.py", line 55, in inner
    response = get_response(request)
  File "C:\Users\asati\AppData\Roaming\Python\Python313\site-packages\django\core\handlers\base.py", line 220, in _get_response
    response = response.render()
  File "C:\Users\asati\AppData\Roaming\Python\Python313\site-packages\django\template\response.py", line 114, in render
    self.content = self.rendered_content
                   ^^^^^^^^^^^^^^^^^^^^^
  File "C:\Users\asati\AppData\Roaming\Python\Python313\site-packages\django\template\response.py", line 90, in rendered_content
    template = self.resolve_template(self.template_name)
  File "C:\Users\asati\AppData\Roaming\Python\Python313\site-packages\django\template\response.py", line 74, in resolve_template
    return get_template(template, using=self.using)
  File "C:\Users\asati\AppData\Roaming\Python\Python313\site-packages\django\template\loader.py", line 19, in get_template
    raise TemplateDoesNotExist(template_name, chain=chain)
django.template.exceptions.TemplateDoesNotExist: sitemap.xml
"GET /sitemap.xml HTTP/1.1" 500 87764
Internal Server Error: /sitemap.xml
Traceback (most recent call last):
  File "C:\Users\asati\AppData\Roaming\Python\Python313\site-packages\django\core\handlers\exception.py", line 55, in inner
    response = get_response(request)
  File "C:\Users\asati\AppData\Roaming\Python\Python313\site-packages\django\core\handlers\base.py", line 220, in _get_response
    response = response.render()
  File "C:\Users\asati\AppData\Roaming\Python\Python313\site-packages\django\template\response.py", line 114, in render
    self.content = self.rendered_content
                   ^^^^^^^^^^^^^^^^^^^^^
  File "C:\Users\asati\AppData\Roaming\Python\Python313\site-packages\django\template\response.py", line 90, in rendered_content
    template = self.resolve_template(self.template_name)
  File "C:\Users\asati\AppData\Roaming\Python\Python313\site-packages\django\template\response.py", line 74, in resolve_template
    return get_template(template, using=self.using)
  File "C:\Users\asati\AppData\Roaming\Python\Python313\site-packages\django\template\loader.py", line 19, in get_template
    raise TemplateDoesNotExist(template_name, chain=chain)
django.template.exceptions.TemplateDoesNotExist: sitemap.xml
"GET /sitemap.xml HTTP/1.1" 500 87764
Internal Server Error: /sitemap.xml
Traceback (most recent call last):
  File "C:\Users\asati\AppData\Roaming\Python\Python313\site-packages\django\core\handlers\exception.py", line 55, in inner
    response = get_response(request)
  File "C:\Users\asati\AppData\Roaming\Python\Python313\site-packages\django\core\handlers\base.py", line 220, in _get_response
    response = response.render()
  File "C:\Users\asati\AppData\Roaming\Python\Python313\site-packages\django\template\response.py", line 114, in render
    self.content = self.rendered_content
                   ^^^^^^^^^^^^^^^^^^^^^
  File "C:\Users\asati\AppData\Roaming\Python\Python313\site-packages\django\template\response.py", line 90, in rendered_content
    template = self.resolve_template(self.template_name)
  File "C:\Users\asati\AppData\Roaming\Python\Python313\site-packages\django\template\response.py", line 74, in resolve_template
    return get_template(template, using=self.using)
  File "C:\Users\asati\AppData\Roaming\Python\Python313\site-packages\django\template\loader.py", line 19, in get_template
    raise TemplateDoesNotExist(template_name, chain=chain)
django.template.exceptions.TemplateDoesNotExist: sitemap.xml
"GET /sitemap.xml HTTP/1.1" 500 87764
Internal Server Error: /sitemap.xml
Traceback (most recent call last):
  File "C:\Users\asati\AppData\Roaming\Python\Python313\site-packages\django\core\handlers\exception.py", line 55, in inner
    response = get_response(request)
  File "C:\Users\asati\AppData\Roaming\Python\Python313\site-packages\django\core\handlers\base.py", line 220, in _get_response
    response = response.render()
  File "C:\Users\asati\AppData\Roaming\Python\Python313\site-packages\django\template\response.py", line 114, in render
    self.content = self.rendered_content
                   ^^^^^^^^^^^^^^^^^^^^^
  File "C:\Users\asati\AppData\Roaming\Python\Python313\site-packages\django\template\response.py", line 90, in rendered_content
    template = self.resolve_template(self.template_name)
  File "C:\Users\asati\AppData\Roaming\Python\Python313\site-packages\django\template\response.py", line 74, in resolve_template
    return get_template(template, using=self.using)
  File "C:\Users\asati\AppData\Roaming\Python\Python313\site-packages\django\template\loader.py", line 19, in get_template
    raise TemplateDoesNotExist(template_name, chain=chain)
django.template.exceptions.TemplateDoesNotExist: sitemap.xml
"GET /sitemap.xml HTTP/1.1" 500 87764
Internal Server Error: /sitemap.xml
Traceback (most recent call last):
  File "C:\Users\asati\AppData\Roaming\Python\Python313\site-packages\django\core\handlers\exception.py", line 55, in inner
    response = get_response(request)
  File "C:\Users\asati\AppData\Roaming\Python\Python313\site-packages\django\core\handlers\base.py", line 220, in _get_response
    response = response.render()
  File "C:\Users\asati\AppData\Roaming\Python\Python313\site-packages\django\template\response.py", line 114, in render
    self.content = self.rendered_content
                   ^^^^^^^^^^^^^^^^^^^^^
  File "C:\Users\asati\AppData\Roaming\Python\Python313\site-packages\django\template\response.py", line 90, in rendered_content
    template = self.resolve_template(self.template_name)
  File "C:\Users\asati\AppData\Roaming\Python\Python313\site-packages\django\template\response.py", line 74, in resolve_template
    return get_template(template, using=self.using)
  File "C:\Users\asati\AppData\Roaming\Python\Python313\site-packages\django\template\loader.py", line 19, in get_template
    raise TemplateDoesNotExist(template_name, chain=chain)
django.template.exceptions.TemplateDoesNotExist: sitemap.xml
"GET /sitemap.xml HTTP/1.1" 500 87764
Internal Server Error: /sitemap.xml
Traceback (most recent call last):
  File "C:\Users\asati\AppData\Roaming\Python\Python313\site-packages\django\template\defaulttags.py", line 1035, in find_library
    return parser.libraries[name]
           ~~~~~~~~~~~~~~~~^^^^^^
KeyError: 'sitemap_tags'

During handling of the above exception, another exception occurred:

Traceback (most recent call last):
  File "C:\Users\asati\AppData\Roaming\Python\Python313\site-packages\django\core\handlers\exception.py", line 55, in inner
    response = get_response(request)
  File "C:\Users\asati\AppData\Roaming\Python\Python313\site-packages\django\core\handlers\base.py", line 220, in _get_response
    response = response.render()
  File "C:\Users\asati\AppData\Roaming\Python\Python313\site-packages\django\template\response.py", line 114, in render
    self.content = self.rendered_content
                   ^^^^^^^^^^^^^^^^^^^^^
  File "C:\Users\asati\AppData\Roaming\Python\Python313\site-packages\django\template\response.py", line 90, in rendered_content
    template = self.resolve_template(self.template_name)
  File "C:\Users\asati\AppData\Roaming\Python\Python313\site-packages\django\template\response.py", line 74, in resolve_template
    return get_template(template, using=self.using)
  File "C:\Users\asati\AppData\Roaming\Python\Python313\site-packages\django\template\loader.py", line 15, in get_template
    return engine.get_template(template_name)
           ~~~~~~~~~~~~~~~~~~~^^^^^^^^^^^^^^^
  File "C:\Users\asati\AppData\Roaming\Python\Python313\site-packages\django\template\backends\django.py", line 79, in get_template
    return Template(self.engine.get_template(template_name), self)
                    ~~~~~~~~~~~~~~~~~~~~~~~~^^^^^^^^^^^^^^^
  File "C:\Users\asati\AppData\Roaming\Python\Python313\site-packages\django\template\engine.py", line 177, in get_template
    template, origin = self.find_template(template_name)
                       ~~~~~~~~~~~~~~~~~~^^^^^^^^^^^^^^^
  File "C:\Users\asati\AppData\Roaming\Python\Python313\site-packages\django\template\engine.py", line 159, in find_template
    template = loader.get_template(name, skip=skip)
  File "C:\Users\asati\AppData\Roaming\Python\Python313\site-packages\django\template\loaders\cached.py", line 57, in get_template
    template = super().get_template(template_name, skip)
  File "C:\Users\asati\AppData\Roaming\Python\Python313\site-packages\django\template\loaders\base.py", line 28, in get_template
    return Template(
        contents,
    ...<2 lines>...
        self.engine,
    )
  File "C:\Users\asati\AppData\Roaming\Python\Python313\site-packages\django\template\base.py", line 154, in __init__
    self.nodelist = self.compile_nodelist()
                    ~~~~~~~~~~~~~~~~~~~~~^^
  File "C:\Users\asati\AppData\Roaming\Python\Python313\site-packages\django\template\base.py", line 196, in compile_nodelist
    nodelist = parser.parse()
  File "C:\Users\asati\AppData\Roaming\Python\Python313\site-packages\django\template\base.py", line 518, in parse
    raise self.error(token, e)
  File "C:\Users\asati\AppData\Roaming\Python\Python313\site-packages\django\template\base.py", line 516, in parse
    compiled_result = compile_func(self, token)
  File "C:\Users\asati\AppData\Roaming\Python\Python313\site-packages\django\template\defaulttags.py", line 1097, in load
    lib = find_library(parser, name)
  File "C:\Users\asati\AppData\Roaming\Python\Python313\site-packages\django\template\defaulttags.py", line 1037, in find_library
    raise TemplateSyntaxError(
    ...<5 lines>...
    )
django.template.exceptions.TemplateSyntaxError: 'sitemap_tags' is not a registered tag library. Must be one of:
admin_list
admin_modify
admin_urls
cache
i18n
l10n
log
static
tz
"GET /sitemap.xml HTTP/1.1" 500 152957
